Workbook

Sheet 大中項目
A1: 機能ID | B1: RSCL | C1: 総件数
A2: 機能名 | B2: RESTクライアント | C2: {=SUMPRODUCT(IF(($A$5:$A$65502<>"")*(LEFT($A$5:$A$65502,4)=$B$1), IFERROR(N(INDIRECT($A$5:$A$65502&"!C2")),0), 0))} -> 80
A4: 大項目ID | B4: 大項目 | C4: 中項目ID | D4: 中項目
A5: =IF(B5="","",($B$1&TEXT(IF(B5="","",COUNTA($B$5:B5)),"00"))) -> RSCL01 | B5: リクエストボディのバッファリング設定（RestTemplate） | C5: =IF(B5="",($B$1&TEXT(IF(B5="",COUNTA($B$5:B5),1),"00")),A5)&IF(B5<>"",TEXT(1,"00"),TEXT(IF(A5<>"",1,RIGHT(C4,2)+1),"00")) -> RSCL0101 | D5: バッファリング設定なしの、Content-lengthの取得の確認
A6: =IF(B6="","",($B$1&TEXT(IF(B6="","",COUNTA($B$5:B6)),"00"))) | C6: =IF(B6="",($B$1&TEXT(IF(B6="",COUNTA($B$5:B6),1),"00")),A6)&IF(B6<>"",TEXT(1,"00"),TEXT(IF(A6<>"",1,RIGHT(C5,2)+1),"00")) -> RSCL0102 | D6: バッファリング設定ありの、Content-lengthの取得の確認
A7: =IF(B7="","",($B$1&TEXT(IF(B7="","",COUNTA($B$5:B7)),"00"))) -> RSCL02 | B7: 各種HttpMessageConverterの確認（RestTemplate） | C7: =IF(B7="",($B$1&TEXT(IF(B7="",COUNTA($B$5:B7),1),"00")),A7)&IF(B7<>"",TEXT(1,"00"),TEXT(IF(A7<>"",1,RIGHT(C6,2)+1),"00")) -> RSCL0201 | D7: ByteArrayHttpMessageConverterを利用した変換
C8: =IF(B8="",($B$1&TEXT(IF(B8="",COUNTA($B$5:B8),1),"00")),A8)&IF(B8<>"",TEXT(1,"00"),TEXT(IF(A8<>"",1,RIGHT(C7,2)+1),"00")) -> RSCL0202 | D8: StringHttpMessageConverterを利用した変換
C9: =IF(B9="",($B$1&TEXT(IF(B9="",COUNTA($B$5:B9),1),"00")),A9)&IF(B9<>"",TEXT(1,"00"),TEXT(IF(A9<>"",1,RIGHT(C8,2)+1),"00")) -> RSCL0203 | D9: ResourceHttpMessageConverterを利用した変換
C10: =IF(B10="",($B$1&TEXT(IF(B10="",COUNTA($B$5:B10),1),"00")),A10)&IF(B10<>"",TEXT(1,"00"),TEXT(IF(A10<>"",1,RIGHT(C9,2)+1),"00")) -> RSCL0204 | D10: SourceHttpMessageConverterを利用した変換
C11: =IF(B11="",($B$1&TEXT(IF(B11="",COUNTA($B$5:B11),1),"00")),A11)&IF(B11<>"",TEXT(1,"00"),TEXT(IF(A11<>"",1,RIGHT(C10,2)+1),"00")) -> RSCL0205 | D11: AllEncompassingFormHttpMessageConverterを利用した変換（メディアタイプがapplication/x-www-form-urlencodedの場合）
C12: =IF(B12="",($B$1&TEXT(IF(B12="",COUNTA($B$5:B12),1),"00")),A12)&IF(B12<>"",TEXT(1,"00"),TEXT(IF(A12<>"",1,RIGHT(C11,2)+1),"00")) -> RSCL0206 | D12: AllEncompassingFormHttpMessageConverterを利用した変換（メディアタイプがmultipart/form-dataの場合）
C13: =IF(B13="",($B$1&TEXT(IF(B13="",COUNTA($B$5:B13),1),"00")),A13)&IF(B13<>"",TEXT(1,"00"),TEXT(IF(A13<>"",1,RIGHT(C12,2)+1),"00")) -> RSCL0207 | D13: JacksonJsonHttpMessageConverterを利用した変換
C14: =IF(B14="",($B$1&TEXT(IF(B14="",COUNTA($B$5:B14),1),"00")),A14)&IF(B14<>"",TEXT(1,"00"),TEXT(IF(A14<>"",1,RIGHT(C13,2)+1),"00")) -> RSCL0208 | D14: Jaxb2RootElementHttpMessageConverterを利用した変換
A15: =IF(B15="","",($B$1&TEXT(IF(B15="","",COUNTA($B$5:B15)),"00"))) -> RSCL03 | B15: BaseURLの設定（RestTemplate） | C15: =IF(B15="",($B$1&TEXT(IF(B15="",COUNTA($B$5:B15),1),"00")),A15)&IF(B15<>"",TEXT(1,"00"),TEXT(IF(A15<>"",1,RIGHT(C14,2)+1),"00")) -> RSCL0301 | D15: BaseURLを設定し、相対URLでのアクセスを確認
C16: =IF(B16="",($B$1&TEXT(IF(B16="",COUNTA($B$5:B16),1),"00")),A16)&IF(B16<>"",TEXT(1,"00"),TEXT(IF(A16<>"",1,RIGHT(C15,2)+1),"00")) -> RSCL0302 | D16: BaseURLを設定し、絶対URLでのアクセスを確認
A17: =IF(B17="","",($B$1&TEXT(IF(B17="","",COUNTA($B$5:B17)),"00"))) -> RSCL04 | B17: 各種HTTPメソッドを利用したアクセスの確認（RestTemplate） | C17: =IF(B17="",($B$1&TEXT(IF(B17="",COUNTA($B$5:B17),1),"00")),A17)&IF(B17<>"",TEXT(1,"00"),TEXT(IF(A17<>"",1,RIGHT(C16,2)+1),"00")) -> RSCL0401 | D17: GETメソッドを指定して、単一件のデータの取得を確認
A18: =IF(B18="","",($B$1&TEXT(IF(B18="","",COUNTA($B$5:B18)),"00"))) | C18: =IF(B18="",($B$1&TEXT(IF(B18="",COUNTA($B$5:B18),1),"00")),A18)&IF(B18<>"",TEXT(1,"00"),TEXT(IF(A18<>"",1,RIGHT(C17,2)+1),"00")) -> RSCL0402 | D18: GETメソッドを指定して、複数件のデータの取得を確認
C19: =IF(B19="",($B$1&TEXT(IF(B19="",COUNTA($B$5:B19),1),"00")),A19)&IF(B19<>"",TEXT(1,"00"),TEXT(IF(A19<>"",1,RIGHT(C18,2)+1),"00")) -> RSCL0403 | D19: POSTメソッドを指定したRestAPIへのアクセスを確認
C20: =IF(B20="",($B$1&TEXT(IF(B20="",COUNTA($B$5:B20),1),"00")),A20)&IF(B20<>"",TEXT(1,"00"),TEXT(IF(A20<>"",1,RIGHT(C19,2)+1),"00")) -> RSCL0404 | D20: PUTメソッドを指定したRestAPIへのアクセスを確認
C21: =IF(B21="",($B$1&TEXT(IF(B21="",COUNTA($B$5:B21),1),"00")),A21)&IF(B21<>"",TEXT(1,"00"),TEXT(IF(A21<>"",1,RIGHT(C20,2)+1),"00")) -> RSCL0405 | D21: PATCHメソッドを指定したRestAPIへのアクセスを確認
C22: =IF(B22="",($B$1&TEXT(IF(B22="",COUNTA($B$5:B22),1),"00")),A22)&IF(B22<>"",TEXT(1,"00"),TEXT(IF(A22<>"",1,RIGHT(C21,2)+1),"00")) -> RSCL0406 | D22: DELETEメソッドを指定したRestAPIへのアクセスを確認
C23: =IF(B23="",($B$1&TEXT(IF(B23="",COUNTA($B$5:B23),1),"00")),A23)&IF(B23<>"",TEXT(1,"00"),TEXT(IF(A23<>"",1,RIGHT(C22,2)+1),"00")) -> RSCL0407 | D23: HEADメソッドを指定したRestAPIへのアクセスを確認
A24: =IF(B24="","",($B$1&TEXT(IF(B24="","",COUNTA($B$5:B24)),"00"))) -> RSCL05 | B24: エラーハンドリングの設定（RestTemplate） | C24: =IF(B24="",($B$1&TEXT(IF(B24="",COUNTA($B$5:B24),1),"00")),A24)&IF(B24<>"",TEXT(1,"00"),TEXT(IF(A24<>"",1,RIGHT(C23,2)+1),"00")) -> RSCL0501 | D24: エラーハンドリング(try-catch)を実装し、レスポンスのステータスが200で返却された場合の挙動を確認
C25: =IF(B25="",($B$1&TEXT(IF(B25="",COUNTA($B$5:B25),1),"00")),A25)&IF(B25<>"",TEXT(1,"00"),TEXT(IF(A25<>"",1,RIGHT(C24,2)+1),"00")) -> RSCL0502 | D25: エラーハンドリング(try-catch)を実装し、レスポンスのステータスが400系で返却された場合の挙動を確認
C26: =IF(B26="",($B$1&TEXT(IF(B26="",COUNTA($B$5:B26),1),"00")),A26)&IF(B26<>"",TEXT(1,"00"),TEXT(IF(A26<>"",1,RIGHT(C25,2)+1),"00")) -> RSCL0503 | D26: エラーハンドリング(try-catch)を実装し、レスポンスのステータスが500系で返却された場合の挙動を確認
C27: =IF(B27="",($B$1&TEXT(IF(B27="",COUNTA($B$5:B27),1),"00")),A27)&IF(B27<>"",TEXT(1,"00"),TEXT(IF(A27<>"",1,RIGHT(C26,2)+1),"00")) -> RSCL0504 | D27: エラーハンドリング(try-catch)を実装し、レスポンスのステータスがユーザー定義のコードで返却された場合の挙動を確認
C28: =IF(B28="",($B$1&TEXT(IF(B28="",COUNTA($B$5:B28),1),"00")),A28)&IF(B28<>"",TEXT(1,"00"),TEXT(IF(A28<>"",1,RIGHT(C27,2)+1),"00")) -> RSCL0505 | D28: 例外で判定を行うリトライ処理を実装して、リトライ回数が上限に到達しない場合、処理が正常終了するかを確認 （ガイドラインの独自実装の確認）
A29: =IF(B29="","",($B$1&TEXT(IF(B29="","",COUNTA($B$5:B29)),"00"))) | C29: =IF(B29="",($B$1&TEXT(IF(B29="",COUNTA($B$5:B29),1),"00")),A29)&IF(B29<>"",TEXT(1,"00"),TEXT(IF(A29<>"",1,RIGHT(C28,2)+1),"00")) -> RSCL0506 | D29: 例外で判定を行うリトライ処理を実装して、リトライ回数が上限に到達した場合、処理が異常終了するかを確認 （ガイドラインの独自実装の確認）
A30: =IF(B30="","",($B$1&TEXT(IF(B30="","",COUNTA($B$5:B30)),"00"))) | C30: =IF(B30="",($B$1&TEXT(IF(B30="",COUNTA($B$5:B30),1),"00")),A30)&IF(B30<>"",TEXT(1,"00"),TEXT(IF(A30<>"",1,RIGHT(C29,2)+1),"00")) -> RSCL0507 | D30: ステータスコードで判定するロジックを実装し、レスポンスのステータスが200で返却された場合の挙動を確認
C31: =IF(B31="",($B$1&TEXT(IF(B31="",COUNTA($B$5:B31),1),"00")),A31)&IF(B31<>"",TEXT(1,"00"),TEXT(IF(A31<>"",1,RIGHT(C30,2)+1),"00")) -> RSCL0508 | D31: ステータスコードで判定するロジックを実装し、レスポンスのステータスが400系で返却された場合の挙動を確認
A32: =IF(B32="","",($B$1&TEXT(IF(B32="","",COUNTA($B$5:B32)),"00"))) | C32: =IF(B32="",($B$1&TEXT(IF(B32="",COUNTA($B$5:B32),1),"00")),A32)&IF(B32<>"",TEXT(1,"00"),TEXT(IF(A32<>"",1,RIGHT(C31,2)+1),"00")) -> RSCL0509 | D32: ステータスコードで判定するロジックを実装し、レスポンスのステータスが500系で返却された場合の挙動を確認
A33: =IF(B33="","",($B$1&TEXT(IF(B33="","",COUNTA($B$5:B33)),"00"))) | C33: =IF(B33="",($B$1&TEXT(IF(B33="",COUNTA($B$5:B33),1),"00")),A33)&IF(B33<>"",TEXT(1,"00"),TEXT(IF(A33<>"",1,RIGHT(C32,2)+1),"00")) -> RSCL0510 | D33: ステータスコードで判定するロジックを実装し、レスポンスのステータスがユーザー定義のコードで返却された場合の挙動を確認
A34: =IF(B34="","",($B$1&TEXT(IF(B34="","",COUNTA($B$5:B34)),"00"))) | C34: =IF(B34="",($B$1&TEXT(IF(B34="",COUNTA($B$5:B34),1),"00")),A34)&IF(B34<>"",TEXT(1,"00"),TEXT(IF(A34<>"",1,RIGHT(C33,2)+1),"00")) -> RSCL0511 | D34: ステータスコードで判定するロジックを実装し、レスポンスのステータスが200で返却された場合の挙動を確認 （NoOpResponseErrorHandlerを使用）
C35: =IF(B35="",($B$1&TEXT(IF(B35="",COUNTA($B$5:B35),1),"00")),A35)&IF(B35<>"",TEXT(1,"00"),TEXT(IF(A35<>"",1,RIGHT(C34,2)+1),"00")) -> RSCL0512 | D35: ステータスコードで判定するロジックを実装し、レスポンスのステータスが400系で返却された場合の挙動を確認 （NoOpResponseErrorHandlerを使用）
A36: =IF(B36="","",($B$1&TEXT(IF(B36="","",COUNTA($B$5:B36)),"00"))) | C36: =IF(B36="",($B$1&TEXT(IF(B36="",COUNTA($B$5:B36),1),"00")),A36)&IF(B36<>"",TEXT(1,"00"),TEXT(IF(A36<>"",1,RIGHT(C35,2)+1),"00")) -> RSCL0513 | D36: ステータスコードで判定するロジックを実装し、レスポンスのステータスが500系で返却された場合の挙動を確認 （NoOpResponseErrorHandlerを使用）
A37: =IF(B37="","",($B$1&TEXT(IF(B37="","",COUNTA($B$5:B37)),"00"))) | C37: =IF(B37="",($B$1&TEXT(IF(B37="",COUNTA($B$5:B37),1),"00")),A37)&IF(B37<>"",TEXT(1,"00"),TEXT(IF(A37<>"",1,RIGHT(C36,2)+1),"00")) -> RSCL0514 | D37: ステータスコードで判定するロジックを実装し、レスポンスのステータスがユーザー定義のコードで返却された場合の挙動を確認 （NoOpResponseErrorHandlerを使用）
C38: =IF(B38="",($B$1&TEXT(IF(B38="",COUNTA($B$5:B38),1),"00")),A38)&IF(B38<>"",TEXT(1,"00"),TEXT(IF(A38<>"",1,RIGHT(C37,2)+1),"00")) -> RSCL0515 | D38: ステータスコードで判定を行うリトライ処理を実装して、リトライ回数が上限に到達しない場合、処理が正常終了するかを確認 （ガイドラインの独自実装の確認）
C39: =IF(B39="",($B$1&TEXT(IF(B39="",COUNTA($B$5:B39),1),"00")),A39)&IF(B39<>"",TEXT(1,"00"),TEXT(IF(A39<>"",1,RIGHT(C38,2)+1),"00")) -> RSCL0516 | D39: ステータスコードで判定を行うリトライ処理を実装して、リトライ回数が上限に到達した場合、処理が異常終了するかを確認 （ガイドラインの独自実装の確認）
A40: =IF(B40="","",($B$1&TEXT(IF(B40="","",COUNTA($B$5:B40)),"00"))) -> RSCL06 | B40: 共通リクエストヘッダの設定（RestTemplate） | C40: =IF(B40="",($B$1&TEXT(IF(B40="",COUNTA($B$5:B40),1),"00")),A40)&IF(B40<>"",TEXT(1,"00"),TEXT(IF(A40<>"",1,RIGHT(C39,2)+1),"00")) -> RSCL0601 | D40: 共通リクエストヘッダの設定を行い、リクエストヘッダが付与されるかを確認
A41: =IF(B41="","",($B$1&TEXT(IF(B41="","",COUNTA($B$5:B41)),"00"))) -> RSCL07 | B41: 認証の設定（RestTemplate） | C41: =IF(B41="",($B$1&TEXT(IF(B41="",COUNTA($B$5:B41),1),"00")),A41)&IF(B41<>"",TEXT(1,"00"),TEXT(IF(A41<>"",1,RIGHT(C40,2)+1),"00")) -> RSCL0701 | D41: 正しい資格情報の認証ヘッダ(Basic)を付与して、RestAPIの認証が正常に通ることを確認
...

Sheet RSCL01
A1: 試験項目表 | C1: 件数 | D1: 機能ID/機能名 | E1: 大項目ID/大項目名 | F1: 作成者/作成日 | G1: 更新者/更新日 | H1: レビュー実施者/ レビュー日
A2: 大中項目へ | C2: =COUNTA($D$9:$D$65483) -> 2 | D2: =大中項目!B1 -> RSCL | E2: {=MID(CELL("filename", A1), FIND("]", CELL("filename", A1)) + 1, 255)} -> RSCL01
D3: =大中項目!B2 -> RESTクライアント | E3: =INDEX(大中項目!B:B, MATCH(E2, 大中項目!A:A, 0)) -> リクエストボディのバッファリング設定（RestTemplate）
A5: 特記事項
A6: 特になし
A8: 中項目ID | B8: Case ID | C8: 分類 | D8: 試験項目 | E8: 試験条件 | F8: 試験条件詳細【事前条件】 | G8: 試験条件詳細【実施条件】 | H8: 確認内容 | I8: 確認方法
A9: RSCL0101 | B9: =IF(A9<>"",1,INDIRECT(ADDRESS(ROW(B9)-1,COLUMN(B9),4))+1) -> 1 | C9: 正常 | D9: バッファリング設定なしの、Content-lengthの取得の確認 | E9: ①RestTemplateのbean定義を行う。 | F9: - | G9: ①入力値は以下の通り name: test0101 age: 30 ②送信ボタン押下 | H9: バッファリングされていないことを確認 ①確認画面に遷移すること ②出力値は以下の通りとなること name: test0101_created age: 30 ③Content-Lengthがnullとなること | I9: Selenium:○
A10: RSCL0102 | B10: =IF(A10<>"",1,INDIRECT(ADDRESS(ROW(B10)-1,COLUMN(B10),4))+1) -> 1 | C10: 正常 | D10: バッファリング設定ありの、Content-lengthの取得の確認 | E10: ①RestTemplateのbean定義を行う。 ②バッファリングする設定を行う。 | F10: - | G10: ①入力値は以下の通り name: test0102 age: 30 ②送信ボタン押下 | H10: バッファリングされていることを確認 ①確認画面に遷移すること ②出力値は以下の通りとなること name: test0102_created age: 30 ③Content-Lengthが取得できること | I10: Selenium:○

Sheet RSCL02
A1: 試験項目表 | C1: 件数 | D1: 機能ID/機能名 | E1: 大項目ID/大項目名 | F1: 作成者/作成日 | G1: 更新者/更新日 | H1: レビュー実施者/ レビュー日
A2: 大中項目へ | C2: =COUNTA($D$9:$D$65491) -> 8 | D2: =大中項目!B1 -> RSCL | E2: {=MID(CELL("filename", A1), FIND("]", CELL("filename", A1)) + 1, 255)} -> RSCL02
D3: =大中項目!B2 -> RESTクライアント | E3: =INDEX(大中項目!B:B, MATCH(E2, 大中項目!A:A, 0)) -> 各種HttpMessageConverterの確認（RestTemplate）
A5: 特記事項
A6: 特になし
A8: 中項目ID | B8: Case ID | C8: 分類 | D8: 試験項目 | E8: 試験条件 | F8: 試験条件詳細【事前条件】 | G8: 試験条件詳細【実施条件】 | H8: 確認内容 | I8: 確認方法
A9: RSCL0201 | B9: =IF(A9<>"",1,INDIRECT(ADDRESS(ROW(B9)-1,COLUMN(B9),4))+1) -> 1 | C9: 正常 | D9: REST APIを呼び出し、Byte配列を送受信することで、ByteArrayHttpMessageConverterが適用されたことを確認する。 | E9: ①RestTemplateのbean定義を行う。 ②HttpMessageConverterがデフォルト登録されていること ③Context-Typeヘッダに「application/octet-stream」を設定すること。 | F9: 以下の１行が書き込まれたファイルを、byte配列に変換してREST APIへ送信する。 １行目：send byte\r\n | G9: ①入力値は以下の通り message: send byte ②送信ボタン押下 | H9: メディアタイプに対応した変換が行われることを確認。 ①確認画面に遷移すること ②表示されているリストのサイズが2であること ③出力値は以下の通りとなること。 １行目：send byte ２行目：_received ④対向先のRestAPIが正しく呼ばれること。 ⑤Context-Typeヘッダに「application/octet-stream」が設定されていること。 | I9: Selenium:○
A10: RSCL0202 | B10: =IF(A10<>"",1,INDIRECT(ADDRESS(ROW(B10)-1,COLUMN(B10),4))+1) -> 1 | C10: 正常 | D10: REST APIを呼び出し、文字列を送受信することで、StringHttpMessageConverterが適用されたことを確認する。 | E10: ①RestTemplateのbean定義を行う。 ②HttpMessageConverterがデフォルト登録されていること ③Context-TypeとAcceptヘッダに「text/plain」を設定すること。 | F10: 以下文字列をREST APIへ送信する。 文字列：sendString | G10: ①入力値は以下の通り message: sendString ②送信ボタン押下 | H10: メディアタイプに対応した変換が行われることを確認。 ①確認画面に遷移すること ②出力値は以下の通りとなること。 sendString_received ③対向先のRestAPIが正しく呼ばれること。 ④Context-Typeヘッダに「text/plain」が設定されていること。 ⑤Acceptヘッダに「text/plain」が設定されていること。 | I10: Selenium:○
A11: RSCL0203 | B11: =IF(A11<>"",1,INDIRECT(ADDRESS(ROW(B11)-1,COLUMN(B11),4))+1) -> 1 | C11: 正常 | D11: REST APIを呼び出し、Resourceを送受信することで、ResourceHttpMessageConverterが適用されたことを確認する。 | E11: ①RestTemplateのbean定義を行う。 ②HttpMessageConverterがデフォルト登録されていること ③Context-Typeヘッダに「application/octet-stream」を設定すること。 | F11: 以下の１行が書き込まれたファイルを、FileSystemResourceに格納してREST APIへ送信する。 １行目：send resource\r\n | G11: ①入力値は以下の通り message: send resource ②送信ボタン押下 | H11: メディアタイプに対応した変換が行われることを確認。 ①確認画面に遷移すること ②表示されているリストのサイズが2であること ③出力値は以下の通りとなること。 １行目：send resource ２行目：_received ④対向先のRestAPIが正しく呼ばれること。 ⑤Context-Typeヘッダに「application/octet-stream」が設定されていること。 | I11: Selenium:○
A12: RSCL0204 | B12: =IF(A12<>"",1,INDIRECT(ADDRESS(ROW(B12)-1,COLUMN(B12),4))+1) -> 1 | C12: 正常 | D12: REST APIを呼び出し、Sourceを送受信することで、SourceHttpMessageConverterが適用されたことを確認する。 | E12: ①RestTemplateのbean定義を行う。 ②HttpMessageConverterに、SourceHttpMessageConverterを設定する。 ③Context-TypeとAcceptヘッダに「application/xml」を設定すること。 | F12: 以下のXMLが書き込まれたDOMSourceを作成してREST APIへ送信する。 <user> <name>test</name> <age>20</age> </user> | G12: ①入力値は以下の通り name: test0204 age: 20 ②送信ボタン押下 | H12: メディアタイプに対応した変換が行われることを確認。 ①確認画面に遷移すること ②出力値は以下の通りとなること。 name:test0204_created age:20 ③対向先のRestAPIが正しく呼ばれること。 ④Context-Typeヘッダに「application/xml」が設定されていること。 ⑤Acceptヘッダに「application/xml」が設定されていること。 | I12: Selenium:○
A13: RSCL0205 | B13: =IF(A13<>"",1,INDIRECT(ADDRESS(ROW(B13)-1,COLUMN(B13),4))+1) -> 1 | C13: 正常 | D13: REST APIを呼び出し、MultiValueMap<String, String>を送受信することで、AllEncompassingFormHttpMessageConverterが適用されたことを確認する。 | E13: ①RestTemplateのbean定義を行う。 ②HttpMessageConverterがデフォルト登録されていること ③Context-TypeとAcceptヘッダに「application/x-www-form-urlencoded」を設定すること。 | F13: 以下のMultiValueMap<String, String>を作成してREST APIへ送信する。 キー：値 name：test0205 age：20 | G13: ①入力値は以下の通り name: test0205 age: 20 ②送信ボタン押下 | H13: メディアタイプに対応した変換が行われることを確認。 ①確認画面に遷移すること ②出力値は以下の通りとなること。 name:test0205_received age:20 ③対向先のRestAPIが正しく呼ばれること。 ④Context-Typeヘッダに「application/x-www-form-urlencoded」が設定されていること。 ⑤Acceptヘッダに「application/x-www-form-urlencoded」が設定されていること。 | I13: Selenium:○
A14: RSCL0206 | B14: =IF(A14<>"",1,INDIRECT(ADDRESS(ROW(B14)-1,COLUMN(B14),4))+1) -> 1 | C14: クライアントエラー | D14: REST APIを呼び出し、MultiValueMap<String, Object>を送信し、AllEncompassingFormHttpMessageConverterが適用され、受信に失敗することを確認する。 | E14: ①RestTemplateのbean定義を行う。 ②HttpMessageConverterがデフォルト登録されていること ③Context-TypeとAcceptヘッダに「multipart/form-data」を設定すること。 | F14: 以下のMultiValueMap<String, Object>を作成してREST APIへ送信する。 キー：値 name：test0205 age：20 | G14: ①入力値は以下の通り name: test0206 age: 20 ②送信ボタン押下 | H14: メディアタイプに対応していない変換は失敗することを確認。 ①システムエラーの画面に遷移すること ②org.springframework.web.HttpMediaTypeNotSupportedExceptionが発生していること | I14: Selenium:○
A15: RSCL0207 | B15: =IF(A15<>"",1,INDIRECT(ADDRESS(ROW(B15)-1,COLUMN(B15),4))+1) -> 1 | C15: 正常 | D15: REST APIを呼び出し、JSONでJavaBeanの送受信を行うことで、JacksonJsonHttpMessageConverterが適用されたことを確認する。 | E15: ①RestTemplateのbean定義を行う。 ②HttpMessageConverterがデフォルト登録されていること ③Context-TypeとAcceptヘッダに「application/json」を設定すること。 | F15: 以下のオブジェクトを作成し、REST APIへ送信する。 Userオブジェクト name = "test0209" age = 20 | G15: ①入力値は以下の通り name: test0209 age: 20 ②送信ボタン押下 | H15: メディアタイプに対応した変換が行われることを確認。 ①確認画面に遷移すること ②出力値は以下の通りとなること。 name:test0209_received age:20 ③対向先のRestAPIが正しく呼ばれること。 ④Context-Typeヘッダに「application/json」が設定されていること。 ⑤Acceptヘッダに「application/json」が設定されていること。 | I15: Selenium:○
A16: RSCL0208 | B16: =IF(A16<>"",1,INDIRECT(ADDRESS(ROW(B16)-1,COLUMN(B16),4))+1) -> 1 | C16: 正常 | D16: REST APIを呼び出し、XMLでJavaBeanの送受信を行うことで、Jaxb2RootElementHttpMessageConverterが適用されたことを確認する。 | E16: ①RestTemplateのbean定義を行う。 ②HttpMessageConverterがデフォルト登録されていること ③Context-TypeとAcceptヘッダに「application/xml」を設定すること。 | F16: 以下のオブジェクトを作成し、REST APIへ送信する。 Userオブジェクト name = "test0211" age = 20 | G16: ①入力値は以下の通り name: test0211 age: 20 ②送信ボタン押下 | H16: メディアタイプに対応した変換が行われることを確認。 ①確認画面に遷移すること ②出力値は以下の通りとなること。 name:test0211_received age:20 ③対向先のRestAPIが正しく呼ばれること。 ④Context-Typeヘッダに「application/xml」が設定されていること。 ⑤Acceptヘッダに「application/xml」が設定されていること。 | I16: Selenium:○

Sheet RSCL03
A1: 試験項目表 | C1: 件数 | D1: 機能ID/機能名 | E1: 大項目ID/大項目名 | F1: 作成者/作成日 | G1: 更新者/更新日 | H1: レビュー実施者/ レビュー日
A2: 大中項目へ | C2: =COUNTA($D$9:$D$65494) -> 2 | D2: =大中項目!B1 -> RSCL | E2: {=MID(CELL("filename", A1), FIND("]", CELL("filename", A1)) + 1, 255)} -> RSCL03
D3: =大中項目!B2 -> RESTクライアント | E3: =INDEX(大中項目!B:B, MATCH(E2, 大中項目!A:A, 0)) -> BaseURLの設定（RestTemplate）
A5: 特記事項
A6: 特になし
A8: 中項目ID | B8: Case ID | C8: 分類 | D8: 試験項目 | E8: 試験条件 | F8: 試験条件詳細【事前条件】 | G8: 試験条件詳細【実施条件】 | H8: 確認内容 | I8: 確認方法
A9: RSCL0301 | B9: =IF(A9<>"",1,INDIRECT(ADDRESS(ROW(B9)-1,COLUMN(B9),4))+1) -> 1 | C9: 正常 | D9: BaseURLを設定し、相対URLでのアクセスを確認 | E9: ①RestTemplateのbean定義を行う。 ②BaseURLの設定を行う。 | F9: テストアプリ内部では相対URLで指定 | G9: ※メニューからリンクを押下するのみ | H9: 相対URLでRestAPIを呼び出せることを確認。 ①確認画面に遷移すること ②出力値は以下の通りとなること。 name:test age:20 ③対向先のRestAPIが正しく呼ばれること。 | I9: Selenium:○
A10: RSCL0302 | B10: =IF(A10<>"",1,INDIRECT(ADDRESS(ROW(B10)-1,COLUMN(B10),4))+1) -> 1 | C10: 正常 | D10: BaseURLを設定し、絶対URLでのアクセスを確認 | E10: ①RestTemplateのbean定義を行う。 ②BaseURLの設定を行う。 | F10: テストアプリ内部では絶対URLで指定 | G10: ※メニューからリンクを押下するのみ | H10: 絶対URLでRestAPIを呼び出せることを確認。 ①確認画面に遷移すること ②出力値は以下の通りとなること。 name:test2 age:25 ③対向先のRestAPIが正しく呼ばれること。 | I10: Selenium:○

Sheet RSCL04
A1: 試験項目表 | C1: 件数 | D1: 機能ID/機能名 | E1: 大項目ID/大項目名 | F1: 作成者/作成日 | G1: 更新者/更新日 | H1: レビュー実施者/ レビュー日
A2: 大中項目へ | C2: =COUNTA($D$9:$D$65495) -> 7 | D2: =大中項目!B1 -> RSCL | E2: {=MID(CELL("filename", A1), FIND("]", CELL("filename", A1)) + 1, 255)} -> RSCL04
D3: =大中項目!B2 -> RESTクライアント | E3: =INDEX(大中項目!B:B, MATCH(E2, 大中項目!A:A, 0)) -> 各種HTTPメソッドを利用したアクセスの確認（RestTemplate）
A5: 特記事項
A6: 特になし
A8: 中項目ID | B8: Case ID | C8: 分類 | D8: 試験項目 | E8: 試験条件 | F8: 試験条件詳細【事前条件】 | G8: 試験条件詳細【実施条件】 | H8: 確認内容 | I8: 確認方法
A9: RSCL0401 | B9: =IF(A9<>"",1,INDIRECT(ADDRESS(ROW(B9)-1,COLUMN(B9),4))+1) -> 1 | C9: 正常 | D9: GETメソッドを指定して、単一件のデータの取得を確認 | E9: ①RestTemplateのbean定義を行う。 | F9: テストアプリ内でGETメソッドを指定 | G9: ※メニューからリンクを押下するのみ | H9: GETメソッドを指定してRestAPI（単一件）を呼び出せることを確認。 ①確認画面に遷移すること ②出力値は以下の通りとなること。 name:test_00001 age:20 ③対向先のRestAPIが正しく呼ばれること。 | I9: Selenium:○
A10: RSCL0402 | B10: =IF(A10<>"",1,INDIRECT(ADDRESS(ROW(B10)-1,COLUMN(B10),4))+1) -> 1 | C10: 正常 | D10: GETメソッドを指定して、複数件のデータの取得を確認 | E10: ①RestTemplateのbean定義を行う。 | F10: テストアプリ内でGETメソッドを指定 | G10: ※メニューからリンクを押下するのみ | H10: GETメソッドを指定してRestAPI（複数件）を呼び出せることを確認。 ①確認画面に遷移すること ②出力件数が5になること。 ③出力値は以下の通りとなること。 name:test1 age:21 name:test2 age:22 name:test3 age:23 name:test4 age:24 name:test5 age:25 ③対向先のRestAPIが正しく呼ばれること。 | I10: Selenium:○
A11: RSCL0403 | B11: =IF(A11<>"",1,INDIRECT(ADDRESS(ROW(B11)-1,COLUMN(B11),4))+1) -> 1 | C11: 正常 | D11: POSTメソッドを指定したRestAPIへのアクセスを確認 | E11: ①RestTemplateのbean定義を行う。 | F11: テストアプリ内でPOSTメソッドを指定 | G11: ①入力値は以下の通り name: test0403 age: 20 ②送信ボタン押下 | H11: POSTメソッドを指定してRestAPIを呼び出せることを確認。 ①確認画面に遷移すること ②出力値は以下の通りとなること。 name:test0403_created age:20 ③対向先のRestAPIが正しく呼ばれること。 | I11: Selenium:○
A12: RSCL0404 | B12: =IF(A12<>"",1,INDIRECT(ADDRESS(ROW(B12)-1,COLUMN(B12),4))+1) -> 1 | C12: 正常 | D12: PUTメソッドを指定したRestAPIへのアクセスを確認 | E12: ①RestTemplateのbean定義を行う。 | F12: テストアプリ内でPUTメソッドを指定 | G12: ①入力値は以下の通り name: test0404 age: 20 ②送信ボタン押下 | H12: PUTメソッドを指定してRestAPIを呼び出せることを確認。 ①確認画面に遷移すること ②出力値は以下の通りとなること。 name:test0404_put age:20 ③対向先のRestAPIが正しく呼ばれること。 | I12: Selenium:○
A13: RSCL0405 | B13: =IF(A13<>"",1,INDIRECT(ADDRESS(ROW(B13)-1,COLUMN(B13),4))+1) -> 1 | C13: 正常 | D13: PATCHメソッドを指定したRestAPIへのアクセスを確認 | E13: ①RestTemplateのbean定義を行う。 | F13: テストアプリ内でPATCHメソッドを指定 | G13: ①入力値は以下の通り name: test0405 age: 20 ②送信ボタン押下 | H13: PATCHメソッドを指定してRestAPIを呼び出せることを確認。 ①確認画面に遷移すること ②出力値は以下の通りとなること。 name:test0405_patch age:20 ③対向先のRestAPIが正しく呼ばれること。 | I13: Selenium:○
A14: RSCL0406 | B14: =IF(A14<>"",1,INDIRECT(ADDRESS(ROW(B14)-1,COLUMN(B14),4))+1) -> 1 | C14: 正常 | D14: DELETEメソッドを指定したRestAPIへのアクセスを確認 | E14: ①RestTemplateのbean定義を行う。 | F14: テストアプリ内でDELETEメソッドを指定 | G14: ※メニューからリンクを押下するのみ | H14: DELETEメソッドを指定してRestAPIを呼び出せることを確認。 ①確認画面に遷移すること ②対向先のRestAPIが正しく呼ばれること。 | I14: Selenium:○
A15: RSCL0407 | B15: =IF(A15<>"",1,INDIRECT(ADDRESS(ROW(B15)-1,COLUMN(B15),4))+1) -> 1 | C15: 正常 | D15: HEADメソッドを指定したRestAPIへのアクセスを確認 | E15: ①RestTemplateのbean定義を行う。 | F15: テストアプリ内でHEADメソッドを指定 | G15: ※メニューからリンクを押下するのみ | H15: HEADメソッドを指定してRestAPIを呼び出せることを確認。 ①確認画面に遷移すること ②対向先のRestAPIが正しく呼ばれること。 | I15: Selenium:○

Sheet RSCL05
A1: 試験項目表 | C1: 件数 | D1: 機能ID/機能名 | E1: 大項目ID/大項目名 | F1: 作成者/作成日 | G1: 更新者/更新日 | H1: レビュー実施者/ レビュー日
A2: 大中項目へ | C2: =COUNTA($D$9:$D$65499) -> 16 | D2: =大中項目!B1 -> RSCL | E2: {=MID(CELL("filename", A1), FIND("]", CELL("filename", A1)) + 1, 255)} -> RSCL05
D3: =大中項目!B2 -> RESTクライアント | E3: =INDEX(大中項目!B:B, MATCH(E2, 大中項目!A:A, 0)) -> エラーハンドリングの設定（RestTemplate）
A5: 特記事項
A6: 特になし
A8: 中項目ID | B8: Case ID | C8: 分類 | D8: 試験項目 | E8: 試験条件 | F8: 試験条件詳細【事前条件】 | G8: 試験条件詳細【実施条件】 | H8: 確認内容 | I8: 確認方法
A9: RSCL0501 | B9: =IF(A9<>"",1,INDIRECT(ADDRESS(ROW(B9)-1,COLUMN(B9),4))+1) -> 1 | C9: 正常 | D9: エラーハンドリング(try-catch)を実装し、レスポンスのステータスが200で返却された場合の挙動を確認 | E9: ①RestTemplateのbean定義を行う。 | F9: テストアプリ内でレスポンスのステータスコードを200で返却 | G9: ※メニューからリンクを押下するのみ | H9: 例外ハンドリングが正しく行われることを確認。 ①確認画面に遷移すること ②出力値は以下の通りとなること。 name:exceptionTest age:20 ③対向先のRestAPIが正しく呼ばれること。 ④レスポンスボディが取得できること。 | I9: Selenium:○
A10: RSCL0502 | B10: =IF(A10<>"",1,INDIRECT(ADDRESS(ROW(B10)-1,COLUMN(B10),4))+1) -> 1 | C10: サーバーエラー | D10: エラーハンドリング(try-catch)を実装し、レスポンスのステータスが400系で返却された場合の挙動を確認 | E10: ①RestTemplateのbean定義を行う。 | F10: テストアプリ内でレスポンスのステータスコードを404で返却 | G10: ※メニューからリンクを押下するのみ | H10: 例外ハンドリングが正しく行われることを確認。 ①システムエラー画面に遷移すること ②対向先のRestAPIが正しく呼ばれること。 ③例外のステータスコードから404が取得できること。 ④catchした例外は、org.springframework.web.client.HttpClientErrorExceptionであること。 | I10: Selenium:○
A11: RSCL0503 | B11: =IF(A11<>"",1,INDIRECT(ADDRESS(ROW(B11)-1,COLUMN(B11),4))+1) -> 1 | C11: サーバーエラー | D11: エラーハンドリング(try-catch)を実装し、レスポンスのステータスが500系で返却された場合の挙動を確認 | E11: ①RestTemplateのbean定義を行う。 | F11: テストアプリ内でレスポンスのステータスコードを500で返却 | G11: ※メニューからリンクを押下するのみ | H11: 例外ハンドリングが正しく行われることを確認。 ①システムエラー画面に遷移すること ②対向先のRestAPIが正しく呼ばれること。 ③例外のステータスコードから500が取得できること。 ④catchした例外は、org.springframework.web.client.HttpServerErrorExceptionであること。 | I11: Selenium:○
A12: RSCL0504 | B12: =IF(A12<>"",1,INDIRECT(ADDRESS(ROW(B12)-1,COLUMN(B12),4))+1) -> 1 | C12: サーバーエラー | D12: エラーハンドリング(try-catch)を実装し、レスポンスのステータスがユーザー定義のコードで返却された場合の挙動を確認 | E12: ①RestTemplateのbean定義を行う。 | F12: テストアプリ内でレスポンスのステータスコードを901で返却 | G12: ※メニューからリンクを押下するのみ | H12: 例外ハンドリングが正しく行われることを確認。 ①確認画面に遷移すること ②出力値は以下の通りとなること。 name:exceptionTest age:20 ③対向先のRestAPIが正しく呼ばれること。 ④レスポンスボディが取得できること。 | I12: Selenium:○
A13: RSCL0505 | B13: =IF(A13<>"",1,INDIRECT(ADDRESS(ROW(B13)-1,COLUMN(B13),4))+1) -> 1 | C13: 正常 | D13: 例外で判定を行うリトライ処理を実装して、リトライ回数が上限に到達しない場合、処理が正常終了するかを確認 （ガイドラインの独自実装の確認） | E13: ①RestTemplateのbean定義を行う。 ②リトライ処理を実装する。 | F13: リトライ3回目で正常なレスポンスを受信する | G13: ※メニューからリンクを押下するのみ | H13: リトライロジックが正常に動作することを確認 ①確認画面に遷移すること ②出力値は以下の通りとなること。 name:test age:20 ③対向先のRestAPIが3回呼ばれること。 ④レスポンスボディが取得できること。 | I13: Selenium:○
A14: RSCL0506 | B14: =IF(A14<>"",1,INDIRECT(ADDRESS(ROW(B14)-1,COLUMN(B14),4))+1) -> 1 | C14: クライアントエラー | D14: 例外で判定を行うリトライ処理を実装して、リトライ回数が上限に到達した場合、処理が異常終了するかを確認 （ガイドラインの独自実装の確認） | E14: ①RestTemplateのbean定義を行う。 ②リトライ処理を実装する。 | F14: リトライ4回目で正常なレスポンスを受信する | G14: ※メニューからリンクを押下するのみ | H14: リトライロジックが正常に動作することを確認 ①システムエラー画面に遷移すること ②対向先のRestAPIが3回呼ばれること。 ③リトライ上限数を超えたメッセージが出力されていること ④catchした例外は、org.springframework.web.client.HttpServerErrorExceptionであること。 | I14: Selenium:○
A15: RSCL0507 | B15: =IF(A15<>"",1,INDIRECT(ADDRESS(ROW(B15)-1,COLUMN(B15),4))+1) -> 1 | C15: 正常 | D15: ステータスコードで判定するロジックを実装し、レスポンスのステータスが200で返却された場合の挙動を確認 | E15: ①RestTemplateのbean定義を行う。 ②例外を無視するエラーハンドラーを設定する | F15: テストアプリ内でレスポンスのステータスコードを200で返却 | G15: ※メニューからリンクを押下するのみ | H15: HTTPステータスコードで、例外ハンドリングが正しく行われることを確認。 ①確認画面に遷移すること ②出力値は以下の通りとなること。 name:exceptionTest age:20 ③対向先のRestAPIが正しく呼ばれること。 ④レスポンスボディが取得できること。 ⑤ステータスコードが200であること。 | I15: Selenium:○
A16: RSCL0508 | B16: =IF(A16<>"",1,INDIRECT(ADDRESS(ROW(B16)-1,COLUMN(B16),4))+1) -> 1 | C16: サーバーエラー | D16: ステータスコードで判定するロジックを実装し、レスポンスのステータスが400系で返却された場合の挙動を確認 | E16: ①RestTemplateのbean定義を行う。 ②例外を無視するエラーハンドラーを設定する | F16: テストアプリ内でレスポンスのステータスコードを404で返却 | G16: ※メニューからリンクを押下するのみ | H16: HTTPステータスコードで、例外ハンドリングが正しく行われることを確認。 ①確認画面に遷移すること ②出力値は以下の通りとなること。 name:空 age:空 ③対向先のRestAPIが正しく呼ばれること。 ④ステータスコードが200であること。 | I16: Selenium:○
A17: RSCL0509 | B17: =IF(A17<>"",1,INDIRECT(ADDRESS(ROW(B17)-1,COLUMN(B17),4))+1) -> 1 | C17: サーバーエラー | D17: ステータスコードで判定するロジックを実装し、レスポンスのステータスが500系で返却された場合の挙動を確認 | E17: ①RestTemplateのbean定義を行う。 ②例外を無視するエラーハンドラーを設定する | F17: テストアプリ内でレスポンスのステータスコードを500で返却 | G17: ※メニューからリンクを押下するのみ | H17: HTTPステータスコードで、例外ハンドリングが正しく行われることを確認。 ①確認画面に遷移すること ②出力値は以下の通りとなること。 name:空 age:空 ③対向先のRestAPIが正しく呼ばれること。 ④ステータスコードが500であること。 | I17: Selenium:○
A18: RSCL0510 | B18: =IF(A18<>"",1,INDIRECT(ADDRESS(ROW(B18)-1,COLUMN(B18),4))+1) -> 1 | C18: サーバーエラー | D18: ステータスコードで判定するロジックを実装し、レスポンスのステータスがユーザー定義のコードで返却された場合の挙動を確認 | E18: ①RestTemplateのbean定義を行う。 ②例外を無視するエラーハンドラーを設定する | F18: テストアプリ内でレスポンスのステータスコードを901で返却 | G18: ※メニューからリンクを押下するのみ | H18: HTTPステータスコードで、例外ハンドリングが正しく行われることを確認。 ①確認画面に遷移すること ②出力値は以下の通りとなること。 name:exceptionTest age:20 ③対向先のRestAPIが正しく呼ばれること。 ④レスポンスボディが取得できること。 ⑤ステータスコードが901であること。 | I18: Selenium:○
A19: RSCL0511 | B19: =IF(A19<>"",1,INDIRECT(ADDRESS(ROW(B19)-1,COLUMN(B19),4))+1) -> 1 | C19: 正常 | D19: ステータスコードで判定するロジックを実装し、レスポンスのステータスが200で返却された場合の挙動を確認 （NoOpResponseErrorHandler使用） | E19: ①RestTemplateのbean定義を行う。 ②例外を無視するエラーハンドラー（NoOpResponseErrorHandler使用）を設定する | F19: テストアプリ内でレスポンスのステータスコードを200で返却 | G19: ※メニューからリンクを押下するのみ | H19: HTTPステータスコードで、例外ハンドリングが正しく行われることを確認。 ①確認画面に遷移すること ②出力値は以下の通りとなること。 name:exceptionTest age:20 ③対向先のRestAPIが正しく呼ばれること。 ④レスポンスボディが取得できること。 ⑤ステータスコードが200であること。 | I19: Selenium:○
A20: RSCL0512 | B20: =IF(A20<>"",1,INDIRECT(ADDRESS(ROW(B20)-1,COLUMN(B20),4))+1) -> 1 | C20: サーバーエラー | D20: ステータスコードで判定するロジックを実装し、レスポンスのステータスが400系で返却された場合の挙動を確認 （NoOpResponseErrorHandler使用） | E20: ①RestTemplateのbean定義を行う。 ②例外を無視するエラーハンドラー（NoOpResponseErrorHandler使用）を設定する | F20: テストアプリ内でレスポンスのステータスコードを404で返却 | G20: ※メニューからリンクを押下するのみ | H20: HTTPステータスコードで、例外ハンドリングが正しく行われることを確認。 ①確認画面に遷移すること ②出力値は以下の通りとなること。 name:空 age:空 ③対向先のRestAPIが正しく呼ばれること。 ④ステータスコードが404であること。 | I20: Selenium:○
... A24: RSCL0516 | B24: =IF(A24<>"",1,INDIRECT(ADDRESS(ROW(B24)-1,COLUMN(B24),4))+1) -> 1 | C24: クライアントエラー | D24: ステータスコードで判定を行うリトライ処理を実装して、リトライ回数が上限に到達した場合、処理が異常終了するかを確認 （ガイドラインの独自実装の確認） | E24: ①RestTemplateのbean定義を行う。 ②例外を無視するエラーハンドラーを設定する ③リトライ処理を実装する。 | F24: リトライ4回目で正常なレスポンスを受信する | G24: ※メニューからリンクを押下するのみ | H24: HTTPステータスコードで、リトライロジックが正常に動作することを確認。 ①確認画面に遷移すること ②出力値は以下の通りとなること。 name:空 age:空 ③対向先のRestAPIが3回呼ばれること。 ④リトライ上限数を超えたメッセージが出力されていること | I24: Selenium:○

Sheet RSCL06
A1: 試験項目表 | C1: 件数 | D1: 機能ID/機能名 | E1: 大項目ID/大項目名 | F1: 作成者/作成日 | G1: 更新者/更新日 | H1: レビュー実施者/ レビュー日
A2: 大中項目へ | C2: =COUNTA($D$9:$D$65492) -> 1 | D2: =大中項目!B1 -> RSCL | E2: {=MID(CELL("filename", A1), FIND("]", CELL("filename", A1)) + 1, 255)} -> RSCL06
D3: =大中項目!B2 -> RESTクライアント | E3: =INDEX(大中項目!B:B, MATCH(E2, 大中項目!A:A, 0)) -> 共通リクエストヘッダの設定（RestTemplate）
A5: 特記事項
A6: 特になし
A8: 中項目ID | B8: Case ID | C8: 分類 | D8: 試験項目 | E8: 試験条件 | F8: 試験条件詳細【事前条件】 | G8: 試験条件詳細【実施条件】 | H8: 確認内容 | I8: 確認方法
A9: RSCL0601 | B9: =IF(A9<>"",1,INDIRECT(ADDRESS(ROW(B9)-1,COLUMN(B9),4))+1) -> 1 | C9: 正常 | D9: 共通リクエストヘッダの設定を行い、リクエストヘッダが付与されるかを確認 | E9: ①RestTemplateのbean定義を行う。 ②カスタムヘッダを付与するClientHttpRequestInitializerを設定する。 | F9: アプリ内の設定で以下のヘッダを付与。 Custom-Header：CustomHeaderValue | G9: ※メニューからリンクを押下するのみ | H9: リクエストヘッダが付与されることを確認 ①確認画面に遷移すること ②出力値は以下の通りとなること。 name:ｔest age:20 ③対向先のRestAPIが正しく呼ばれること。 ④以下ヘッダが付与されていること。 Custom-Header：CustomHeaderValue | I9: Selenium:○

Sheet RSCL07
A1: 試験項目表 | C1: 件数 | D1: 機能ID/機能名 | E1: 大項目ID/大項目名 | F1: 作成者/作成日 | G1: 更新者/更新日 | H1: レビュー実施者/ レビュー日
A2: 大中項目へ | C2: =COUNTA($D$9:$D$65492) -> 3 | D2: =大中項目!B1 -> RSCL | E2: {=MID(CELL("filename", A1), FIND("]", CELL("filename", A1)) + 1, 255)} -> RSCL07
D3: =大中項目!B2 -> RESTクライアント | E3: =INDEX(大中項目!B:B, MATCH(E2, 大中項目!A:A, 0)) -> 認証の設定（RestTemplate）
A5: 特記事項
A6: 特になし
A8: 中項目ID | B8: Case ID | C8: 分類 | D8: 試験項目 | E8: 試験条件 | F8: 試験条件詳細【事前条件】 | G8: 試験条件詳細【実施条件】 | H8: 確認内容 | I8: 確認方法
A9: RSCL0701 | B9: =IF(A9<>"",1,INDIRECT(ADDRESS(ROW(B9)-1,COLUMN(B9),4))+1) -> 1 | C9: 正常 | D9: 正しい資格情報の認証ヘッダ(Basic)を付与して、RestAPIの認証が正常に通ることを確認 | E9: ①RestTemplateのbean定義を行う。 ②認証ヘッダを付与するClientHttpRequestInitializerを設定する。 | F9: アプリ内の設定で以下のヘッダを付与。 Authorization：Basic 資格情報 | G9: ※メニューからリンクを押下するのみ | H9: 正常に認証が通ることを確認 ①確認画面に遷移すること ②出力値は以下の通りとなること。 name:ｔest age:20 ③対向先のRestAPIが正しく呼ばれること。 ④以下ヘッダが付与されていること。 Authorization：Basic 資格情報 | I9: Selenium:○
A10: RSCL0702 | B10: =IF(A10<>"",1,INDIRECT(ADDRESS(ROW(B10)-1,COLUMN(B10),4))+1) -> 1 | C10: サーバーエラー | D10: 誤った資格情報の認証ヘッダ(Basic)を付与して、RestAPIの認証が通らないことを確認 | E10: ①RestTemplateのbean定義を行う。 ②認証ヘッダを付与するClientHttpRequestInitializerを設定する。 | F10: アプリ内の設定で以下のヘッダを付与。 Authorization：Basic 資格情報（誤り） | G10: ※メニューからリンクを押下するのみ | H10: 認証が失敗することを確認 ①システムエラー画面に遷移すること ②以下例外が発生していること。 org.springframework.web.client.HttpClientErrorException | I10: Selenium:○
A11: RSCL0703 | B11: =IF(A11<>"",1,INDIRECT(ADDRESS(ROW(B11)-1,COLUMN(B11),4))+1) -> 1 | C11: サーバーエラー | D11: 認証ヘッダ(Basic)を付与せずRestAPIへアクセスした際に、RestAPIの認証が通らないことを確認 | E11: ①RestTemplateのbean定義を行う。 | F11: - | G11: ※メニューからリンクを押下するのみ | H11: 認証が失敗することを確認 ①システムエラー画面に遷移すること ②以下例外が発生していること。 org.springframework.web.client.HttpClientErrorException | I11: Selenium:○

Sheet RSCL08
A1: 試験項目表 | C1: 件数 | D1: 機能ID/機能名 | E1: 大項目ID/大項目名 | F1: 作成者/作成日 | G1: 更新者/更新日 | H1: レビュー実施者/ レビュー日
A2: 大中項目へ | C2: =COUNTA($D$9:$D$65491) -> 2 | D2: =大中項目!B1 -> RSCL | E2: {=MID(CELL("filename", A1), FIND("]", CELL("filename", A1)) + 1, 255)} -> RSCL08
D3: =大中項目!B2 -> RESTクライアント | E3: =INDEX(大中項目!B:B, MATCH(E2, 大中項目!A:A, 0)) -> タイムアウト設定（RestTemplate）
A5: 特記事項
A6: 特になし
A8: 中項目ID | B8: Case ID | C8: 分類 | D8: 試験項目 | E8: 試験条件 | F8: 試験条件詳細【事前条件】 | G8: 試験条件詳細【実施条件】 | H8: 確認内容 | I8: 確認方法
A9: RSCL0801 | B9: =IF(A9<>"",1,INDIRECT(ADDRESS(ROW(B9)-1,COLUMN(B9),4))+1) -> 1 | C9: クライアントエラー | D9: Connect Timeoutを設定し、指定した時間でコネクション確立のタイムアウトが発生することを確認 | E9: ①RestTemplateのbean定義を行う。 ②Connect Timeoutを設定したRequestFactoryを設定 | F9: URLの接続先がアクセスできないドメインとなっている | G9: ※メニューからリンクを押下するのみ | H9: タイムアウトが発生することを確認。 ①システムエラー画面に遷移すること ②以下例外が発生していること。 org.springframework.web.client.ResourceAccessException ③内包されている例外が以下の通りであること。 org.apache.hc.client5.http.ConnectTimeoutException | I9: Selenium:○
A10: RSCL0802 | B10: =IF(A10<>"",1,INDIRECT(ADDRESS(ROW(B10)-1,COLUMN(B10),4))+1) -> 1 | C10: サーバーエラー | D10: Read Timeoutを設定し、指定した時間でレスポンス受信のタイムアウトが発生することを確認 | E10: ①RestTemplateのbean定義を行う。 ②Read Timeoutを設定したRequestFactoryを設定 | F10: レスポンスがタイムアウト上限を超えるように、アプリ内でスリープを行う。 | G10: ※メニューからリンクを押下するのみ | H10: タイムアウトが発生することを確認。 ①システムエラー画面に遷移すること ②対向先のRestAPIが正しく呼ばれること。 ③以下例外が発生していること。 org.springframework.web.client.ResourceAccessException ④内包されている例外が以下の通りであること。 java.net.SocketTimeoutException | I10: Selenium:○

Sheet RSCL09
A1: 試験項目表 | C1: 件数 | D1: 機能ID/機能名 | E1: 大項目ID/大項目名 | F1: 作成者/作成日 | G1: 更新者/更新日 | H1: レビュー実施者/ レビュー日
A2: 大中項目へ | C2: =COUNTA($D$9:$D$65495) -> 1 | D2: =大中項目!B1 -> RSCL | E2: {=MID(CELL("filename", A1), FIND("]", CELL("filename", A1)) + 1, 255)} -> RSCL09
D3: =大中項目!B2 -> RESTクライアント | E3: =INDEX(大中項目!B:B, MATCH(E2, 大中項目!A:A, 0)) -> ファイルアップロード（RestTemplate）
A5: 特記事項
A6: 特になし
A8: 中項目ID | B8: Case ID | C8: 分類 | D8: 試験項目 | E8: 試験条件 | F8: 試験条件詳細【事前条件】 | G8: 試験条件詳細【実施条件】 | H8: 確認内容 | I8: 確認方法
A9: RSCL0901 | B9: =IF(A9<>"",1,INDIRECT(ADDRESS(ROW(B9)-1,COLUMN(B9),4))+1) -> 1 | C9: 正常 | D9: ファイルのアップロードを確認 | E9: ①RestTemplateのbean定義を行う。 | F9: ・アプリ内でContent-Typeにmultipart/form-dataを設定。 ・ファイルをResource型に変換してマルチパートに設定。 | G9: ※メニューからリンクを押下するのみ | H9: multipart/form-dataでデータを送信できることを確認。 ①確認画面に遷移すること ②出力値は以下の通りとなること。 name:uploadTest age:31 ③対向先のRestAPIが正しく呼ばれること。 | I9: Selenium:○

Sheet RSCL10
A1: 試験項目表 | C1: 件数 | D1: 機能ID/機能名 | E1: 大項目ID/大項目名 | F1: 作成者/作成日 | G1: 更新者/更新日 | H1: レビュー実施者/ レビュー日
A2: 大中項目へ | C2: =COUNTA($D$9:$D$65496) -> 6 | D2: =大中項目!B1 -> RSCL | E2: {=MID(CELL("filename", A1), FIND("]", CELL("filename", A1)) + 1, 255)} -> RSCL10
D3: =大中項目!B2 -> RESTクライアント | E3: =INDEX(大中項目!B:B, MATCH(E2, 大中項目!A:A, 0)) -> ファイルダウンロード（RestTemplate）
A5: 特記事項
A6: 特になし
A8: 中項目ID | B8: Case ID | C8: 分類 | D8: 試験項目 | E8: 試験条件 | F8: 試験条件詳細【事前条件】 | G8: 試験条件詳細【実施条件】 | H8: 確認内容 | I8: 確認方法
A9: RSCL1001 | B9: =IF(A9<>"",1,INDIRECT(ADDRESS(ROW(B9)-1,COLUMN(B9),4))+1) -> 1 | C9: 正常 | D9: レスポンスボディをByte型で受信して、ファイルダウンロードを行えるかを確認 | E9: ①RestTemplateのbean定義を行う。 | F9: アプリ内でByte型でレスポンスボディを受信する。 | G9: ※メニューからリンクを押下するのみ | H9: 特定の型でデータをダウンロードできることを確認。 ①確認画面に遷移すること ②出力件数が1000であること ③出力値は以下の通りとなること。 name:test0 age:30 ～ name:test999 age30 ④対向先のRestAPIが正しく呼ばれること。 | I9: Selenium:○
A10: RSCL1002 | B10: =IF(A10<>"",1,INDIRECT(ADDRESS(ROW(B10)-1,COLUMN(B10),4))+1) -> 1 | C10: 正常 | D10: レスポンスボディをResource型で受信して、ファイルダウンロードを行えるかを確認 | E10: ①RestTemplateのbean定義を行う。 | F10: アプリ内でResource型でレスポンスボディを受信する。 | G10: ※メニューからリンクを押下するのみ | H10: 特定の型でデータをダウンロードできることを確認。 ①確認画面に遷移すること ②出力件数が1000であること ③出力値は以下の通りとなること。 name:test0 age:30 ～ name:test999 age30 ④対向先のRestAPIが正しく呼ばれること。 | I10: Selenium:○
A11: RSCL1003 | B11: =IF(A11<>"",1,INDIRECT(ADDRESS(ROW(B11)-1,COLUMN(B11),4))+1) -> 1 | C11: 正常 | D11: レスポンスボディをInputStream型で受信して、ファイルダウンロードを行えるかを確認 | E11: ①RestTemplateのbean定義を行う。 | F11: ResponseExtractorにてレスポンスボディをInputStreamで取得する | G11: ※メニューからリンクを押下するのみ | H11: 特定の型でデータをダウンロードできることを確認。 ①確認画面に遷移すること ②出力件数が1000であること ③出力値は以下の通りとなること。 name:test0 age:30 ～ name:test999 age30 ④対向先のRestAPIが正しく呼ばれること。 | I11: Selenium:○
A12: RSCL1004 | B12: =IF(A12<>"",1,INDIRECT(ADDRESS(ROW(B12)-1,COLUMN(B12),4))+1) -> 1 | C12: サーバーエラー | D12: レスポンスボディをInputStream型で受信して、404のステータスコードが返却された場合にエラーとなるかを確認 | E12: ①RestTemplateのbean定義を行う。 | F12: ・ResponseExtractorにてレスポンスボディをInputStreamで取得する ・テストアプリ内でレスポンスのステータスコードを404で返却 | G12: ※メニューからリンクを押下するのみ | H12: エラーとなることを確認。 ①システムエラー画面に遷移すること ②対向先のRestAPIが正しく呼ばれること。 ③catchした例外は、org.springframework.web.client.HttpClientErrorExceptionであること。 | I12: Selenium:○
A13: RSCL1005 | B13: =IF(A13<>"",1,INDIRECT(ADDRESS(ROW(B13)-1,COLUMN(B13),4))+1) -> 1 | C13: 正常 | D13: ResponseExtractorでレスポンス情報を設定し、呼び出し後に取得が行えるかを確認 | E13: ①RestTemplateのbean定義を行う。 | F13: ResponseExtractorにてレスポンスボディをInputStreamで取得する | G13: ※メニューからリンクを押下するのみ | H13: レスポンス情報が取得できることを確認。 ①確認画面に遷移すること ②出力件数が1000であること ③出力値は以下の通りとなること。 name:test0 age:30 ～ name:test999 age30 ④対向先のRestAPIが正しく呼ばれること。 ⑤ステータスコードが200であること。 | I13: Selenium:○
A14: RSCL1006 | B14: =IF(A14<>"",1,INDIRECT(ADDRESS(ROW(B14)-1,COLUMN(B14),4))+1) -> 1 | C14: サーバーエラー | D14: ResponseExtractorでレスポンス情報を設定し、異常なデータを受信時にエラーとなることを確認 | E14: ①RestTemplateのbean定義を行う。 | F14: ・ResponseExtractorにてレスポンスボディをInputStreamで取得する ・テストアプリ内でレスポンスのステータスコードを404で返却 | G14: ※メニューからリンクを押下するのみ | H14: エラーとなることを確認。 ①システムエラー画面に遷移すること ②対向先のRestAPIが正しく呼ばれること。 ③catchした例外は、org.springframework.web.client.HttpClientErrorExceptionであること。 | I14: Selenium:○

Sheet RSCL11
A1: 試験項目表 | C1: 件数 | D1: 機能ID/機能名 | E1: 大項目ID/大項目名 | F1: 作成者/作成日 | G1: 更新者/更新日 | H1: レビュー実施者/ レビュー日
A2: 大中項目へ | C2: =COUNTA($D$9:$D$65491) -> 2 | D2: =大中項目!B1 -> RSCL | E2: {=MID(CELL("filename", A1), FIND("]", CELL("filename", A1)) + 1, 255)} -> RSCL11
D3: =大中項目!B2 -> RESTクライアント | E3: =INDEX(大中項目!B:B, MATCH(E2, 大中項目!A:A, 0)) -> レスポンス情報の取得、リクエスト情報の設定（RestTemplate）
A5: 特記事項
A6: 特になし
A8: 中項目ID | B8: Case ID | C8: 分類 | D8: 試験項目 | E8: 試験条件 | F8: 試験条件詳細【事前条件】 | G8: 試験条件詳細【実施条件】 | H8: 確認内容 | I8: 確認方法
A9: RSCL1101 | B9: =IF(A9<>"",1,INDIRECT(ADDRESS(ROW(B9)-1,COLUMN(B9),4))+1) -> 1 | C9: 正常 | D9: RestAPIからレスポンスを受信した際に、レスポンスボディ以外の情報も取得が行えることを確認 | E9: ①RestTemplateのbean定義を行う。 | F9: - | G9: ※メニューからリンクを押下するのみ | H9: レスポンス情報が取得できることを確認。 ①確認画面に遷移すること ②出力値は以下の通りとなること。 httpStatus:200 responseHeader:何かしらの値が入っている responseBody:User [name=test, age=20] ③対向先のRestAPIが正しく呼ばれること。 | I9: Selenium:○
A10: RSCL1102 | B10: =IF(A10<>"",1,INDIRECT(ADDRESS(ROW(B10)-1,COLUMN(B10),4))+1) -> 1 | C10: 正常 | D10: RestAPIへリクエストを送信する際に、リクエストに対してヘッダの設定が行えることを確認 | E10: ①RestTemplateのbean定義を行う。 | F10: 呼び出し時に以下のヘッダを付与。 Custom-Header：Custom-Value | G10: ※メニューからリンクを押下するのみ | H10: リクエストヘッダが付与されることを確認。 ①確認画面に遷移すること ②出力値は以下の通りとなること。 httpStatus:200 responseHeader:何かしらの値が入っている responseBody:User [name=test, age=20] ③対向先のRestAPIが正しく呼ばれること。 ④以下ヘッダが付与されていること。 Custom-Header：Custom-Value | I10: Selenium:○

Sheet RSCL12
A1: 試験項目表 | C1: 件数 | D1: 機能ID/機能名 | E1: 大項目ID/大項目名 | F1: 作成者/作成日 | G1: 更新者/更新日 | H1: レビュー実施者/ レビュー日
A2: 大中項目へ | C2: =COUNTA($D$9:$D$65495) -> 3 | D2: =大中項目!B1 -> RSCL | E2: {=MID(CELL("filename", A1), FIND("]", CELL("filename", A1)) + 1, 255)} -> RSCL12
D3: =大中項目!B2 -> RESTクライアント | E3: =INDEX(大中項目!B:B, MATCH(E2, 大中項目!A:A, 0)) -> 個別のリクエストヘッダの設定（RestTemplate）
A5: 特記事項
A6: 特になし
A8: 中項目ID | B8: Case ID | C8: 分類 | D8: 試験項目 | E8: 試験条件 | F8: 試験条件詳細【事前条件】 | G8: 試験条件詳細【実施条件】 | H8: 確認内容 | I8: 確認方法
A9: RSCL1201 | B9: =IF(A9<>"",1,INDIRECT(ADDRESS(ROW(B9)-1,COLUMN(B9),4))+1) -> 1 | C9: 正常 | D9: クライアント実行時にリクエストヘッダの設定を行い、リクエストヘッダ（Content-Type）が付与されるかを確認 | E9: ①RestTemplateのbean定義を行う。 | F9: 呼び出し時に以下のヘッダを付与。 Content-Type：application/json | G9: ①入力値は以下の通り name: test1201 age: 35 ②送信ボタン押下 | H9: リクエストヘッダが付与されることを確認。 ①確認画面に遷移すること ②出力値は以下の通りとなること。 name:ｔest1201_created age:35 ③対向先のRestAPIが正しく呼ばれること。 ④以下ヘッダが付与されていること。 Content-Type：application/json | I9: Selenium:○
A10: RSCL1202 | B10: =IF(A10<>"",1,INDIRECT(ADDRESS(ROW(B10)-1,COLUMN(B10),4))+1) -> 1 | C10: 正常 | D10: クライアント実行時にリクエストヘッダの設定を行い、リクエストヘッダ（Accept）が付与されるかを確認 | E10: ①RestTemplateのbean定義を行う。 | F10: 呼び出し時に以下のヘッダを付与。 Accept：application/json | G10: ※メニューからリンクを押下するのみ | H10: リクエストヘッダが付与されることを確認。 ①確認画面に遷移すること ②出力値は以下の通りとなること。 name:test age:20 ③対向先のRestAPIが正しく呼ばれること。 ④以下ヘッダが付与されていること。 Accept：application/json | I10: Selenium:○
A11: RSCL1203 | B11: =IF(A11<>"",1,INDIRECT(ADDRESS(ROW(B11)-1,COLUMN(B11),4))+1) -> 1 | C11: 正常 | D11: クライアント実行時にリクエストヘッダの設定を行い、リクエストヘッダ（カスタムヘッダ）が付与されるかを確認 | E11: ①RestTemplateのbean定義を行う。 | F11: 呼び出し時に以下のヘッダを付与。 Custom-Header：CustomValue | G11: ※メニューからリンクを押下するのみ | H11: リクエストヘッダが付与されることを確認。 ①確認画面に遷移すること ②出力値は以下の通りとなること。 name:test age:20 ③対向先のRestAPIが正しく呼ばれること。 ④以下ヘッダが付与されていること。 Custom-Header：CustomValue | I11: Selenium:○

Sheet RSCL13
A1: 試験項目表 | C1: 件数 | D1: 機能ID/機能名 | E1: 大項目ID/大項目名 | F1: 作成者/作成日 | G1: 更新者/更新日 | H1: レビュー実施者/ レビュー日
A2: 大中項目へ | C2: =COUNTA($D$9:$D$65488) -> 1 | D2: =大中項目!B1 -> RSCL | E2: {=MID(CELL("filename", A1), FIND("]", CELL("filename", A1)) + 1, 255)} -> RSCL13
D3: =大中項目!B2 -> RESTクライアント | E3: =INDEX(大中項目!B:B, MATCH(E2, 大中項目!A:A, 0)) -> 埋め込みパラメータのカスタマイズ設定（RestTemplate）
A5: 特記事項
A6: 特になし
A8: 中項目ID | B8: Case ID | C8: 分類 | D8: 試験項目 | E8: 試験条件 | F8: 試験条件詳細【事前条件】 | G8: 試験条件詳細【実施条件】 | H8: 確認内容 | I8: 確認方法
A9: RSCL1301 | B9: =IF(A9<>"",1,INDIRECT(ADDRESS(ROW(B9)-1,COLUMN(B9),4))+1) -> 1 | C9: 正常 | D9: UriBuilderFactoryをカスタマイズし、LocalDateで設定した日付が、特定の文字列フォーマットに変換されRestAPIに送信されることを確認 | E9: ①RestTemplateのbean定義を行う。 ②カスタムのUriBuilderFactoryを作成する。 ③作成したUriBuilderFactoryを設定する。 | F9: リクエスト送信時に、URLに日付(LocalDate）を設定する。 | G9: ※メニューからリンクを押下するのみ | H9: LocalDateからｙｙｙｙMMddのフォーマット文字列に変換できることを確認。 ①確認画面に遷移すること ②出力値は以下の通りとなること。 orderId:00001 orderDate:20250101 orderItem:Sample Item ③対向先のRestAPIが正しく呼ばれること。 ④RestAPI側で変換後の日付文字列が取得できること。 ⑤CustomUriBuilderFactoryが実行され、LocalDateが指定したフォーマット文字列に変換されていること。 | I9: Selenium:○

Sheet RSCL14
A1: 試験項目表 | C1: 件数 | D1: 機能ID/機能名 | E1: 大項目ID/大項目名 | F1: 作成者/作成日 | G1: 更新者/更新日 | H1: レビュー実施者/ レビュー日
A2: 大中項目へ | C2: =COUNTA($D$9:$D$65495) -> 6 | D2: =大中項目!B1 -> RSCL | E2: {=MID(CELL("filename", A1), FIND("]", CELL("filename", A1)) + 1, 255)} -> RSCL14
D3: =大中項目!B2 -> RESTクライアント | E3: =INDEX(大中項目!B:B, MATCH(E2, 大中項目!A:A, 0)) -> SSL自己署名証明書とSSL通信（RestTemplate）
A5: 特記事項
A6: 特になし
A8: 中項目ID | B8: Case ID | C8: 分類 | D8: 試験項目 | E8: 試験条件 | F8: 試験条件詳細【事前条件】 | G8: 試験条件詳細【実施条件】 | H8: 確認内容 | I8: 確認方法
A9: RSCL1401 | B9: =IF(A9<>"",1,INDIRECT(ADDRESS(ROW(B9)-1,COLUMN(B9),4))+1) -> 1 | C9: 正常 | D9: RestTemplateを使用して、HTTPS接続でREST APIを呼び出し、JavaBeanを取得する。 | E9: ①RestTemplateを使用すること。 ②接続先のREST APIがHTTPS接続可能であること。 ③接続先のRESTAPIが、JavaBeanに対応するレコードを1件返すこと。 | F9: ①RestTemplateのbean定義をしておく。 ②接続先のRESTAPIが、以下のJavaBeanを返却すること。 Userオブジェクト name = "test" age = 20 | G9: - | H9: ①取得したJavaBeanが以下と同値であること。 Userオブジェクト name = "test" age = 20 ②id="screenTitle"のタグの値が以下であること。 "RESTクライアント処理結果【ユーザ情報出力】" | I9: Selenium:○
A10: RSCL1402 | B10: =IF(A10<>"",1,INDIRECT(ADDRESS(ROW(B10)-1,COLUMN(B10),4))+1) -> 1 | C10: 正常 | D10: setMaxConnPerRouteメソッドの動作確認をする。 | E10: 「RSCL14の試験内容図」シートの内容を参照 | F10: 「RSCL14の試験内容図」シートの内容を参照 | G10: 「RSCL14の試験内容図」シートの内容を参照 | H10: ①ブラウザ1/2において取得したJavaBeanが以下と同値であること。 Userオブジェクト name = "test" age = 20 ②id="screenTitle"のタグの値が以下であること。 "RESTクライアント処理結果【ユーザ情報出力】" ③処理時間が、先行処理が6秒前後、後続処理が12秒前後となること | I10: Selenium:○
A11: RSCL1403 | B11: =IF(A11<>"",1,INDIRECT(ADDRESS(ROW(B11)-1,COLUMN(B11),4))+1) -> 1 | C11: 正常 | D11: setMaxConnPerRoute/setMaxConnTotalメソッドの動作確認をする。 | E11: 「RSCL14の試験内容図」シートの内容を参照 | F11: 「RSCL14の試験内容図」シートの内容を参照 | G11: 「RSCL14の試験内容図」シートの内容を参照 | H11: ①ブラウザ1/2/3において取得したJavaBeanが以下と同値であること。 Userオブジェクト name = "test" age = 20 ②id="screenTitle"のタグの値が以下であること。 "RESTクライアント処理結果【ユーザ情報出力】" ③処理時間が、先行処理が6秒前後、後続処理が12秒前後となること | I11: Selenium:○
A12: RSCL1404 | B12: =IF(A12<>"",1,INDIRECT(ADDRESS(ROW(B12)-1,COLUMN(B12),4))+1) -> 1 | C12: 正常 | D12: setConnectTimeoutメソッドの動作確認をする。 | E12: 「RSCL14の試験内容図」シートの内容を参照 | F12: 「RSCL14の試験内容図」シートの内容を参照 | G12: 「RSCL14の試験内容図」シートの内容を参照 | H12: ①システムエラー画面に遷移していること。 ・h1タグとtitleタグの値が"System Error!"であること。 ・以下のログが出力されていること。 ・出力元のロガー名のパターン："org.terasoluna.gfw.common.exception.ExceptionLogger.Monitoring" ・メッセージのパターン："[e.sf.fw.9001]..* failed: Connect timed out" ・スタックトレースに以下の例外が出力されていること ・"jorg.apache.hc.client5.http.ConnectTimeoutException" | I12: Selenium:○
A13: RSCL1405 | B13: =IF(A13<>"",1,INDIRECT(ADDRESS(ROW(B13)-1,COLUMN(B13),4))+1) -> 1 | C13: 正常 | D13: setResponseTimeoutメソッドの動作確認をする。 | E13: 「RSCL14の試験内容図」シートの内容を参照 | F13: 「RSCL14の試験内容図」シートの内容を参照 | G13: 「RSCL14の試験内容図」シートの内容を参照 | H13: ①システムエラー画面に遷移していること。 ・h1タグとtitleタグの値が"System Error!"であること。 ・以下のログが出力されていること。 ・出力元のロガー名のパターン："org.terasoluna.gfw.common.exception.ExceptionLogger.Monitoring" ・メッセージのパターン："[e.sf.fw.9001]..*: Read timed out" ・スタックトレースに以下の例外が出力されていること ・"java.net.SocketTimeoutException" | I13: Selenium:○
A14: RSCL1406 | B14: =IF(A14<>"",1,INDIRECT(ADDRESS(ROW(B14)-1,COLUMN(B14),4))+1) -> 1 | C14: 正常 | D14: setHandshakeTimeoutメソッドの動作確認をする。 | E14: 「RSCL14の試験内容図」シートの内容を参照 | F14: 「RSCL14の試験内容図」シートの内容を参照 | G14: 「RSCL14の試験内容図」シートの内容を参照 | H14: ①取得したJavaBeanが以下と同値であること。 Userオブジェクト name = "test" age = 20 ②SoTimeoutを1msに設定したRestTemplateでSoTimeoutが発生し、以下のメッセージおよびスタックトレースが出力されていること。 ・"[e.sf.fw.9001] System error occurred!" ・"org.apache.hc.client5.http.ConnectTimeoutException" 以下、手動確認項目 コネクションの挙動を確認すること。 netstat -n | grep <サーバのポート番号> 接続が残っている：ESTABLISHED クローズ待ちになった：CLOSE_WAIT 待ち状態：TIME_WAIT 完全にCLOSEされた：なし しばらくの間ESTABLISHEDで残り続ける。 サーバ側の同時実行数が1の場合、SSLハンドシェイクを待ちでコネクションを握ったままの状態となり、正常なRestTemplateでもコネクションが取得できないこと。 | I14: Selenium:○
B18: 【自己証明書作成＆登録手順】
B19: # ①有効期限100年のキーストア作成。キーストアファイル名「rscltest.ks」 keytool -genkey -alias rscltest -keypass pass123 -validity 36500 -keystore rscltest.ks -storepass pass123 -dname "cn=localhost, ou=rscltest, o=rscltest, c=JP" # ②上記で作成したキーストア「rscltest.ks」から証明書をエクスポート。証明書名「rsclserver.cer」 keytool -export -alias rscltest -storepass pass123 -file rsclserver.cer -keystore rscltest.ks # ③上記でエクスポートした証明書「rsclserver.cer」を、Javaのデフォルトのキーストアに登録。Javaのキーストアファイル名「cacerts」 keytool -importcert -alias rscltest -file rsclserver.cer -keystore "%JAVA_HOME%\jre\lib\security\cacerts" -storepass changeit -keypass pass123 # 補足 # Javaのキーストア「cacerts」に登録されている証明書の一覧出力 keytool -list -v -keystore "%JAVA_HOME%\jre\lib\security\cacerts" -storepass changeit # Javaのキーストア「cacerts」から特定の証明書（この例だと、aliasがrscltestのもの）を削除 keytool -delete -alias rscltest -keystore "%JAVA_HOME%\jre\lib\security\cacerts" -storepass changeit

Sheet RSCL14の試験内容図

Sheet RSCL16
A1: 試験項目表 | C1: 件数 | D1: 機能ID/機能名 | E1: 大項目ID/大項目名 | F1: 作成者/作成日 | G1: 更新者/更新日 | H1: レビュー実施者/ レビュー日
A2: 大中項目へ | C2: =COUNTA($D$9:$D$65494) -> 2 | D2: =大中項目!B1 -> RSCL | E2: {=MID(CELL("filename", A1), FIND("]", CELL("filename", A1)) + 1, 255)} -> RSCL16
D3: =大中項目!B2 -> RESTクライアント | E3: =INDEX(大中項目!B:B, MATCH(E2, 大中項目!A:A, 0)) -> カスタムコンバータの設定（RestTemplate）
A5: 特記事項
A6: 特になし
A8: 中項目ID | B8: Case ID | C8: 分類 | D8: 試験項目 | E8: 試験条件 | F8: 試験条件詳細【事前条件】 | G8: 試験条件詳細【実施条件】 | H8: 確認内容 | I8: 確認方法
A9: RSCL1601 | B9: =IF(A9<>"",1,INDIRECT(ADDRESS(ROW(B9)-1,COLUMN(B9),4))+1) -> 1 | C9: 正常 | D9: 独自のメディアタイプを設定したカスタムコンバータを作成し、カスタムコンバータで実装した変換処理が行われるかを確認 | E9: ①RestTemplateのbean定義を行う。 ②カスタムコンバータ（csv⇒Javaオブジェクト）を作成する。 ③カスタムコンバータを設定する。 | F9: 呼び出し時に以下のヘッダを付与。 Accept：text/csv | G9: ※メニューからリンクを押下するのみ | H9: ＣＳＶのデータ形式のレスポンスを受信できることを確認 ①確認画面に遷移すること ②出力件数が5であること ③出力値は以下の通りとなること。 name:testUser1 age:30 name:testUser2 age:31 name:testUser3 age:32 name:testUser4 age:33 name:testUser5 age:34 ④対向先のRestAPIが正しく呼ばれること。 ⑤以下ヘッダが付与されていること。 Accept：text/csv | I9: Selenium:○
A10: RSCL1602 | B10: =IF(A10<>"",1,INDIRECT(ADDRESS(ROW(B10)-1,COLUMN(B10),4))+1) -> 1 | C10: 正常 | D10: 既存のメディアタイプ（application/json）に対して、別のHttpMessageConverterを設定し変換処理が切り替わるかを確認 | E10: ①RestTemplateのbean定義を行う。 ②JacksonJsonHttpMessageConverterを拡張したコンバーターを作成 ③拡張したコンバータを設定する。 | F10: 呼び出し時に以下のヘッダを付与。 Content-Type：application/json Accept：application/json | G10: ①入力値は以下の通り name: test1601 age: 33 ②送信ボタン押下 | H10: 設定したHttpMessageConverterが利用されることを確認。 ①確認画面に遷移すること ②出力値は以下の通りとなること。 name:test1601_created age:33 ③対向先のRestAPIが正しく呼ばれること。 ④以下ヘッダが付与されていること。 Content-Type：application/json Accept：application/json ⑤writeInternalメソッドのログが出力されること ⑥readメソッドのログが出力されること | I10: Selenium:○

Sheet RSCL17
A1: 試験項目表 | C1: 件数 | D1: 機能ID/機能名 | E1: 大項目ID/大項目名 | F1: 作成者/作成日 | G1: 更新者/更新日 | H1: レビュー実施者/ レビュー日
A2: 大中項目へ | C2: =COUNTA($D$9:$D$65494) -> 2 | D2: =大中項目!B1 -> RSCL | E2: {=MID(CELL("filename", A1), FIND("]", CELL("filename", A1)) + 1, 255)} -> RSCL17
D3: =大中項目!B2 -> RESTクライアント | E3: =INDEX(大中項目!B:B, MATCH(E2, 大中項目!A:A, 0)) -> リクエスト送信前後の共通処理設定（RestTemplate）
A5: 特記事項
A6: 特になし
A8: 中項目ID | B8: Case ID | C8: 分類 | D8: 試験項目 | E8: 試験条件 | F8: 試験条件詳細【事前条件】 | G8: 試験条件詳細【実施条件】 | H8: 確認内容 | I8: 確認方法
A9: RSCL1701 | B9: =IF(A9<>"",1,INDIRECT(ADDRESS(ROW(B9)-1,COLUMN(B9),4))+1) -> 1 | C9: 正常 | D9: リクエスト、レスポンスログを出力するInterceptorを設定し、正常にログが出力されるかを確認 | E9: ①RestTemplateのbean定義を行う。 ②リクエスト、レスポンスログを出力するInterceptorを作成する。 ③作成したInterceptorを設定する。 | F9: - | G9: ①入力値は以下の通り name: test1701 age: 32 ②送信ボタン押下 | H9: リクエスト、レスポンスログが出力されていることを確認 ①確認画面に遷移すること ②出力値は以下の通りとなること name: test1701_created age: 32 ③対向先のRestAPIが正しく呼ばれること。 ④リクエストヘッダのログが出力されていること ⑤リクエストボディのログが出力されていること ⑥レスポンスヘッダのログが出力されていること ⑦HTTPステータスコードのログが出力されていること | I9: Selenium:○
A10: RSCL1702 | B10: =IF(A10<>"",1,INDIRECT(ADDRESS(ROW(B10)-1,COLUMN(B10),4))+1) -> 1 | C10: 正常 | D10: 複数のインターセプターを登録し実行順序を確認 | E10: ①RestTemplateのbean定義を行う。 ②イベントログを出力するInterceptorを２つ作成する。 ③作成した２つのInterceptorを設定する。 | F10: - | G10: ※メニューからリンクを押下するのみ | H10: インターセプターの実行順序を示すログが出力されていることを確認 ①確認画面に遷移すること ②出力値は以下の通りとなること。 name:test age:20 ③対向先のRestAPIが正しく呼ばれること。 ④以下の順のログが出力されていること CustomOrder1Interceptor Start!, CustomOrder2Interceptor Start!, CustomOrder2Interceptor End!, CustomOrder1Interceptor End! | I10: Selenium:○

Sheet RSCL18
A1: 試験項目表 | C1: 件数 | D1: 機能ID/機能名 | E1: 大項目ID/大項目名 | F1: 作成者/作成日 | G1: 更新者/更新日 | H1: レビュー実施者/ レビュー日
A2: 大中項目へ | C2: =COUNTA($D$9:$D$65493) -> 2 | D2: =大中項目!B1 -> RSCL | E2: {=MID(CELL("filename", A1), FIND("]", CELL("filename", A1)) + 1, 255)} -> RSCL18
D3: =大中項目!B2 -> RESTクライアント | E3: =INDEX(大中項目!B:B, MATCH(E2, 大中項目!A:A, 0)) -> RESTfulなURL(URIテンプレート)を扱う方法と実装（RestTemplate）
A5: 特記事項
A6: 特になし
A8: 中項目ID | B8: Case ID | C8: 分類 | D8: 試験項目 | E8: 試験条件 | F8: 試験条件詳細【事前条件】 | G8: 試験条件詳細【実施条件】 | H8: 確認内容 | I8: 確認方法
A9: RSCL1801 | B9: =IF(A9<>"",1,INDIRECT(ADDRESS(ROW(B9)-1,COLUMN(B9),4))+1) -> 1 | C9: 正常 | D9: URLの一部に埋め込み文字を定義し、リクエスト送信時（getForObject）にURLに値が埋め込まれるかを確認 | E9: ①RestTemplateのbean定義を行う。 | F9: アプリ内でURLに埋め込み文字を設定する | G9: ※メニューからリンクを押下するのみ | H9: 正しいURL文字列が生成され、対応するRestAPIが呼び出されることを確認。 ①確認画面に遷移すること ②出力値は以下の通りとなること name: test_0001 age: 20 ③対向先のRestAPIが正しく呼ばれること。 ④埋め込みパラメータが以下の通りであること。 Id: 0001 | I9: Selenium:○
A10: RSCL1802 | B10: =IF(A10<>"",1,INDIRECT(ADDRESS(ROW(B10)-1,COLUMN(B10),4))+1) -> 1 | C10: 正常 | D10: URLの一部に埋め込み文字を定義し、リクエスト送信時（exchange）にURLに値が埋め込まれるかを確認 | E10: ①RestTemplateのbean定義を行う。 | F10: アプリ内でURLに埋め込み文字を設定する | G10: ①入力値は以下の通り name: test1802 age: 31 ②送信ボタン押下 | H10: 正しいURL文字列が生成され、対応するRestAPIが呼び出されることを確認。 ①確認画面に遷移すること ②出力値は以下の通りとなること name: test1802_created age: 31 ③対向先のRestAPIが正しく呼ばれること。 ④埋め込みパラメータが以下の通りであること。 Action: create | I10: Selenium:○

Sheet RSCL19
A1: 試験項目表 | C1: 件数 | D1: 機能ID/機能名 | E1: 大項目ID/大項目名 | F1: 作成者/作成日 | G1: 更新者/更新日 | H1: レビュー実施者/ レビュー日
A2: 大中項目へ | C2: =COUNTA($D$9:$D$65493) -> 3 | D2: =大中項目!B1 -> RSCL | E2: {=MID(CELL("filename", A1), FIND("]", CELL("filename", A1)) + 1, 255)} -> RSCL19
D3: =大中項目!B2 -> RESTクライアント | E3: =INDEX(大中項目!B:B, MATCH(E2, 大中項目!A:A, 0)) -> HTTP Proxyの設定（RestTemplate）
A5: 特記事項
A6: 特になし
A8: 中項目ID | B8: Case ID | C8: 分類 | D8: 試験項目 | E8: 試験条件 | F8: 試験条件詳細【事前条件】 | G8: 試験条件詳細【実施条件】 | H8: 確認内容 | I8: 確認方法
A9: RSCL1901 | B9: =IF(A9<>"",1,INDIRECT(ADDRESS(ROW(B9)-1,COLUMN(B9),4))+1) -> 1 | C9: 正常 | D9: Proxyの設定を行い、認証なしのProxyに対してアクセスが行えるかを確認 | E9: ①RestTemplateのbean定義を行う。 ②プロキシ設定を行ったRequestFactoryを設定する。 | F9: - | G9: ※メニューからリンクを押下するのみ | H9: Proxyを経由してRestAPIへアクセスができることを確認。 ①確認画面に遷移すること ②出力値は以下の通りとなること name: test age: 20 ③対向先のRestAPIが正しく呼ばれること。 ④Proxyで設定したレスポンスヘッダが取得できること ⑤Proxyを経由したログが出力されていること。 | I9: Selenium:○
A10: RSCL1902 | B10: =IF(A10<>"",1,INDIRECT(ADDRESS(ROW(B10)-1,COLUMN(B10),4))+1) -> 1 | C10: 正常 | D10: 正しい資格情報のProxy設定を行い、認証ありのProxyに対してアクセスができるかを確認 | E10: ①RestTemplateのbean定義を行う。 ②正しい資格情報のプロキシ設定を行ったRequestFactoryを設定する。 | F10: - | G10: ①入力値は以下の通り name: test1802 age: 31 ②送信ボタン押下 | H10: Proxyを経由してRestAPIへアクセスができることを確認。 ①確認画面に遷移すること ②出力値は以下の通りとなること name: test2 age: 21 ③対向先のRestAPIが正しく呼ばれること。 ④Proxyで設定したレスポンスヘッダが取得できること ⑤Proxyで認証が成功したログが出力されていること。 | I10: Selenium:○
A11: RSCL1903 | B11: =IF(A11<>"",1,INDIRECT(ADDRESS(ROW(B11)-1,COLUMN(B11),4))+1) -> 1 | C11: サーバーエラー | D11: 誤った資格情報のProxy設定を行い、認証ありのProxyに対してアクセスが失敗するかを確認 | E11: ①RestTemplateのbean定義を行う。 ②誤った資格情報のプロキシ設定を行ったRequestFactoryを設定する。 | F11: - | G11: ①入力値は以下の通り name: test1802 age: 31 ②送信ボタン押下 | H11: Proxyで認証エラーとなり、RestAPIへアクセスができないことを確認。 ①システムエラー画面に遷移すること ②Proxyで認証が失敗したログが出力されていること。 ③以下の例外が発生することを確認。 org.springframework.web.client.HttpClientErrorException | I11: Selenium:○

Sheet RSCL48
A1: 試験項目表 | C1: 件数 | D1: 機能ID/機能名 | E1: 大項目ID/大項目名 | F1: 作成者/作成日 | G1: 更新者/更新日 | H1: レビュー実施者/ レビュー日
A2: 大中項目へ | C2: =COUNTA($D$9:$D$65486) -> 2 | D2: =大中項目!B1 -> RSCL | E2: {=MID(CELL("filename", A1), FIND("]", CELL("filename", A1)) + 1, 255)} -> RSCL48
D3: =大中項目!B2 -> RESTクライアント | E3: =INDEX(大中項目!B:B, MATCH(E2, 大中項目!A:A, 0)) -> 非同期通信のデータ登録（WebClient）
A5: 特記事項
A6: 特になし
A8: 中項目ID | B8: Case ID | C8: 分類 | D8: 試験項目 | E8: 試験条件 | F8: 試験条件詳細【事前条件】 | G8: 試験条件詳細【実施条件】 | H8: 確認内容 | I8: 確認方法
A9: RSCL4801 | B9: =IF(A9<>"",1,INDIRECT(ADDRESS(ROW(B9)-1,COLUMN(B9),4))+1) -> 1 | C9: 正常 | D9: CompletableFutureを利用し非同期でデータの一括登録を行い、RestAPIに正常にデータを送信できることを確認 | E9: ①WebClientのbean定義を行う。 ②画面表示を非同期で実行できるようにサーバーを非同期モードで起動 | F9: - | G9: ①送信ボタン押下 | H9: RestAPIへのアクセスが非同期で実行され、結果も非同期で取得できること ①確認画面に遷移すること ②出力値は以下の通りとなること。 httpStatus:200 responseHeader:値が入っていること responseBody:Result [count=20] ③対向先のRestAPIが正しく呼ばれること。 ④リクエスト送信前とリスナーのスレッドが異なること。 ⑤ステータスコードが200で受信できていること。 | I9: Selenium:○
A10: RSCL4802 | B10: =IF(A10<>"",1,INDIRECT(ADDRESS(ROW(B10)-1,COLUMN(B10),4))+1) -> 1 | C10: 正常 | D10: CompletableFutureを利用し同期でデータの一括登録を行い、RestAPIに正常にデータを送信できることを確認 | E10: ①WebClientのbean定義を行う。 | F10: CompletableFutureを同期モード(get)で実行 | G10: ①送信ボタン押下 | H10: RestAPIへのアクセスが非同期で実行され、結果は同期で取得できること ①確認画面に遷移すること ②出力値は以下の通りとなること。 httpStatus:200 responseHeader:値が入っていること responseBody:Result [count=20] ③対向先のRestAPIが正しく呼ばれること。 ④リクエスト送信前とリスナーのスレッドが異なること。 ⑤ステータスコードが200で受信できていること。 | I10: Selenium:○

Sheet RSCL49
A1: 試験項目表 | C1: 件数 | D1: 機能ID/機能名 | E1: 大項目ID/大項目名 | F1: 作成者/作成日 | G1: 更新者/更新日 | H1: レビュー実施者/ レビュー日
A2: 大中項目へ | C2: =COUNTA($D$9:$D$65486) -> 7 | D2: =大中項目!B1 -> RSCL | E2: {=MID(CELL("filename", A1), FIND("]", CELL("filename", A1)) + 1, 255)} -> RSCL49
D3: =大中項目!B2 -> RESTクライアント | E3: =INDEX(大中項目!B:B, MATCH(E2, 大中項目!A:A, 0)) -> エラーハンドリングの設定（WebClient）
A5: 特記事項
A6: 特になし
A8: 中項目ID | B8: Case ID | C8: 分類 | D8: 試験項目 | E8: 試験条件 | F8: 試験条件詳細【事前条件】 | G8: 試験条件詳細【実施条件】 | H8: 確認内容 | I8: 確認方法
A9: RSCL4901 | B9: =IF(A9<>"",1,INDIRECT(ADDRESS(ROW(B9)-1,COLUMN(B9),4))+1) -> 1 | C9: サーバーエラー | D9: エラーハンドリングの設定を行い、該当するステータスコードの場合にステータスハンドラーが実行されることを確認 | E9: ①WebClientのbean定義を行う。 ②エラーをハンドルするdefaultStatusHandlerを設定する ③500系のエラーをハンドルするStatusHandlerを設定する ④画面表示を非同期で実行できるようにサーバーを非同期モードで起動 | F9: テストアプリ内でレスポンスのステータスコードを404で返却 | G9: ※メニューからリンクを押下するのみ | H9: デフォルトのステータスハンドラーが利用されることを確認。 ①システムエラー画面に遷移すること ②対向先のRestAPIが正しく呼ばれること。 ③リクエスト送信前とリスナーのスレッドが異なること。 ③catchした例外は、jp.co.ntt.fw.spring.functionaltest.app.cmmn.exception.CustomExceptionであること。 ④defaultStatusHandlerが呼び出されたログが出力されていること。 | I9: Selenium:○
A10: RSCL4902 | B10: =IF(A10<>"",1,INDIRECT(ADDRESS(ROW(B10)-1,COLUMN(B10),4))+1) -> 1 | C10: サーバーエラー | D10: クライアント実行時にエラーハンドリングの設定を行い、該当するステータスコードの場合にステータスハンドラーが実行されることを確認 | E10: ①WebClientのbean定義を行う。 ②エラーをハンドルするdefaultStatusHandlerを設定する ③500系のエラーをハンドルするStatusHandlerを設定する ④画面表示を非同期で実行できるようにサーバーを非同期モードで起動 | F10: テストアプリ内でレスポンスのステータスコードを500で返却 | G10: ※メニューからリンクを押下するのみ | H10: 個別のステータスハンドラーが利用されることを確認。 ①システムエラー画面に遷移すること ②対向先のRestAPIが正しく呼ばれること。 ③リクエスト送信前とリスナーのスレッドが異なること。 ④catchした例外は、jp.co.ntt.fw.spring.functionaltest.app.cmmn.exception.CustomExceptionであること。 ⑤statusHandlerが呼び出されたログが出力されていること。 | I10: Selenium:○
A11: RSCL4903 | B11: =IF(A11<>"",1,INDIRECT(ADDRESS(ROW(B11)-1,COLUMN(B11),4))+1) -> 1 | C11: 正常 | D11: 非同期結果を受信するリスナーにてエラー処理を実装し、レスポンスのステータスが200で返却された場合の挙動を確認 | E11: ①WebClientのbean定義を行う。 ②画面表示を非同期で実行できるようにサーバーを非同期モードで起動 | F11: テストアプリ内でレスポンスのステータスコードを200で返却 | G11: ※メニューからリンクを押下するのみ | H11: 例外ハンドリングが正しく行われることを確認。 ①確認画面に遷移すること ②出力値は以下の通りとなること。 name:exceptionTest age:20 ③対向先のRestAPIが正しく呼ばれること。 ④リクエスト送信前とリスナーのスレッドが異なること。 ⑤ステータスコードが200で受信できていること。 | I11: Selenium:○
A12: RSCL4904 | B12: =IF(A12<>"",1,INDIRECT(ADDRESS(ROW(B12)-1,COLUMN(B12),4))+1) -> 1 | C12: サーバーエラー | D12: 非同期結果を受信するリスナーにてエラー処理を実装し、レスポンスのステータスが400系で返却された場合の挙動を確認 | E12: ①WebClientのbean定義を行う。 ②画面表示を非同期で実行できるようにサーバーを非同期モードで起動 | F12: テストアプリ内でレスポンスのステータスコードを404で返却 | G12: ※メニューからリンクを押下するのみ | H12: 例外ハンドリングが正しく行われることを確認。 ①システムエラー画面に遷移すること ②対向先のRestAPIが正しく呼ばれること。 ③リクエスト送信前とリスナーのスレッドが異なること。 ④catchした例外は、org.springframework.web.reactive.function.client.WebClientResponseExceptionであること。 ⑤返却されたステータスコードが404であること。 | I12: Selenium:○
A13: RSCL4905 | B13: =IF(A13<>"",1,INDIRECT(ADDRESS(ROW(B13)-1,COLUMN(B13),4))+1) -> 1 | C13: サーバーエラー | D13: 非同期結果を受信するリスナーにてエラー処理を実装し、レスポンスのステータスが500系で返却された場合の挙動を確認 | E13: ①WebClientのbean定義を行う。 ②画面表示を非同期で実行できるようにサーバーを非同期モードで起動 | F13: テストアプリ内でレスポンスのステータスコードを500で返却 | G13: ※メニューからリンクを押下するのみ | H13: 例外ハンドリングが正しく行われることを確認。 ①システムエラー画面に遷移すること ②対向先のRestAPIが正しく呼ばれること。 ③リクエスト送信前とリスナーのスレッドが異なること。 ④catchした例外は、org.springframework.web.reactive.function.client.WebClientResponseExceptionであること。 ⑤返却されたステータスコードが500であること。 | I13: Selenium:○
A14: RSCL4906 | B14: =IF(A14<>"",1,INDIRECT(ADDRESS(ROW(B14)-1,COLUMN(B14),4))+1) -> 1 | C14: サーバーエラー | D14: 非同期結果を受信するリスナーにてエラー処理を実装し、レスポンスのステータスがユーザー定義のコードで返却された場合の挙動を確認 | E14: ①WebClientのbean定義を行う。 ②画面表示を非同期で実行できるようにサーバーを非同期モードで起動 | F14: テストアプリ内でレスポンスのステータスコードを901で返却 | G14: ※メニューからリンクを押下するのみ | H14: 例外ハンドリングが正しく行われることを確認。 ①システムエラー画面に遷移すること ②対向先のRestAPIが正しく呼ばれること。 ③リクエスト送信前とリスナーのスレッドが異なること。 ④catchした例外は、org.springframework.web.reactive.function.client.UnknownHttpStatusCodeExceptionであること。 ⑤返却されたステータスコードが901であること。 | I14: Selenium:○
A15: RSCL4907 | B15: =IF(A15<>"",1,INDIRECT(ADDRESS(ROW(B15)-1,COLUMN(B15),4))+1) -> 1 | C15: クライアントエラー | D15: 非同期結果を受信するリスナーにてエラー処理を実装し、イベントループのストリーム処理中にエラーが発生した場合の挙動を確認 | E15: ①WebClientのbean定義を行う。 ②画面表示を非同期で実行できるようにサーバーを非同期モードで起動 ③ストリームからオブジェクトに展開するメモリサイズを1Mに設定。 | F15: 1M以上のレコードを返却。 | G15: ※メニューからリンクを押下するのみ | H15: 例外ハンドリングが正しく行われることを確認。 ①システムエラー画面に遷移すること ②対向先のRestAPIが正しく呼ばれること。 ③リクエスト送信前とリスナーのスレッドが異なること。 ④catchした例外は、org.springframework.core.io.buffer.DataBufferLimitExceptionであること。 ⑤返却されたステータスコードが200であること。 | I15: Selenium:○

Sheet RSCL50
A1: 試験項目表 | C1: 件数 | D1: 機能ID/機能名 | E1: 大項目ID/大項目名 | F1: 作成者/作成日 | G1: 更新者/更新日 | H1: レビュー実施者/ レビュー日
A2: 大中項目へ | C2: =COUNTA($D$9:$D$65481) -> 2 | D2: =大中項目!B1 -> RSCL | E2: {=MID(CELL("filename", A1), FIND("]", CELL("filename", A1)) + 1, 255)} -> RSCL50
D3: =大中項目!B2 -> RESTクライアント | E3: =INDEX(大中項目!B:B, MATCH(E2, 大中項目!A:A, 0)) -> リクエスト送信前の共通処理設定（WebClient）
A5: 特記事項
A6: 特になし
A8: 中項目ID | B8: Case ID | C8: 分類 | D8: 試験項目 | E8: 試験条件 | F8: 試験条件詳細【事前条件】 | G8: 試験条件詳細【実施条件】 | H8: 確認内容 | I8: 確認方法
A9: RSCL5001 | B9: =IF(A9<>"",1,INDIRECT(ADDRESS(ROW(B9)-1,COLUMN(B9),4))+1) -> 1 | C9: 正常 | D9: ログ出力をするExchangeFilterFunctionを設定し、リクエスト送信前のログが出力されることを確認 | E9: ①WebClientのbean定義を行う。 ②リクエストログを出力するExchangeFilterFunctionを作成。 ③作成したExchangeFilterFunctionを設定 ④画面表示を非同期で実行できるようにサーバーを非同期モードで起動 | F9: - | G9: ①入力値は以下の通り name: test5001 age: 33 ②送信ボタン押下 | H9: リクエスト送信前のログが出力されること ①確認画面に遷移すること ②出力値は以下の通りとなること。 name:test5001_created age:33 ③対向先のRestAPIが正しく呼ばれること。 ④リクエスト送信前とリスナーのスレッドが異なること。 ⑤リクエスト送信前のログが出力されること | I9: Selenium:○
A10: RSCL5002 | B10: =IF(A10<>"",1,INDIRECT(ADDRESS(ROW(B10)-1,COLUMN(B10),4))+1) -> 1 | C10: 正常 | D10: リクエストヘッダを付与するExchangeFilterFunctionを設定し、リクエスト送信時にヘッダが付与されることを確認 | E10: ①WebClientのbean定義を行う。 ②カスタムヘッダを付与するExchangeFilterFunctionを作成。 ③作成したExchangeFilterFunctionを設定 ④画面表示を非同期で実行できるようにサーバーを非同期モードで起動 | F10: - | G10: ※メニューからリンクを押下するのみ | H10: リクエストヘッダが付与されることを確認 ①確認画面に遷移すること ②出力値は以下の通りとなること。 name:test age:20 ③対向先のRestAPIが正しく呼ばれること。 ④以下ヘッダが付与されていること。 Custom-Header: test value ⑤リクエスト送信前とリスナーのスレッドが異なること。 ⑥ExchangeFilterFunctionのログが出力されること | I10: Selenium:○
