Workbook

Sheet 大中項目
A1: 機能ID | B1: OTH2 | C1: 総件数
A2: 機能名 | B2: OAuth2.0 | C2: {=SUMPRODUCT(IF(LEFT($A$5:$A$65497, 4)=$B$1, N(INDIRECT($A$5:$A$65497 & "!C2")), 0))} -> 35
A4: 大項目ID | B4: 大項目 | C4: 中項目ID | D4: 中項目
A5: =IF(B5="","",($B$1&TEXT(IF(B5="","",COUNTA($B$5:B5)),"00"))) -> OTH201 | B5: 認可コードグラント | C5: =IF(B5="",($B$1&TEXT(IF(B5="",COUNTA($B$5:B5),1),"00")),A5)&IF(B5<>"",TEXT(1,"00"),TEXT(IF(A5<>"",1,RIGHT(C4,2)+1),"00")) -> OTH20101 | D5: 全スコープに権限を持つクライアントに対する操作
C6: =IF(B6="",($B$1&TEXT(IF(B6="",COUNTA($B$5:B6),1),"00")),A6)&IF(B6<>"",TEXT(1,"00"),TEXT(IF(A6<>"",1,RIGHT(C5,2)+1),"00")) -> OTH20102 | D6: READスコープのみ権限を持つクライアントに対する操作
C7: =IF(B7="",($B$1&TEXT(IF(B7="",COUNTA($B$5:B7),1),"00")),A7)&IF(B7<>"",TEXT(1,"00"),TEXT(IF(A7<>"",1,RIGHT(C6,2)+1),"00")) -> OTH20103 | D7: 設定スコープと認可サーバ側の設定が合わないクライアントに対する操作
A8: =IF(B8="","",($B$1&TEXT(IF(B8="","",COUNTA($B$5:B8)),"00"))) | C8: =IF(B8="",($B$1&TEXT(IF(B8="",COUNTA($B$5:B8),1),"00")),A8)&IF(B8<>"",TEXT(1,"00"),TEXT(IF(A8<>"",1,RIGHT(C7,2)+1),"00")) -> OTH20104 | D8: 認可サーバ側は全スコープを許容するが、クライアント側でスコープを絞っている場合の操作
A9: =IF(B9="","",($B$1&TEXT(IF(B9="","",COUNTA($B$5:B9)),"00"))) -> OTH202 | B9: アクセストークン | C9: =IF(B9="",($B$1&TEXT(IF(B9="",COUNTA($B$5:B9),1),"00")),A9)&IF(B9<>"",TEXT(1,"00"),TEXT(IF(A9<>"",1,RIGHT(C8,2)+1),"00")) -> OTH20201 | D9: アクセストークン（有効期限）
A10: =IF(B10="","",($B$1&TEXT(IF(B10="","",COUNTA($B$5:B10)),"00"))) | C10: =IF(B10="",($B$1&TEXT(IF(B10="",COUNTA($B$5:B10),1),"00")),A10)&IF(B10<>"",TEXT(1,"00"),TEXT(IF(A10<>"",1,RIGHT(C9,2)+1),"00")) -> OTH20202 | D10: トークンの加工
A11: =IF(B11="","",($B$1&TEXT(IF(B11="","",COUNTA($B$5:B11)),"00"))) -> OTH203 | B11: その他異常系 | C11: =IF(B11="",($B$1&TEXT(IF(B11="",COUNTA($B$5:B11),1),"00")),A11)&IF(B11<>"",TEXT(1,"00"),TEXT(IF(A11<>"",1,RIGHT(C10,2)+1),"00")) -> OTH20301 | D11: 認可サーバからの応答がない
A12: =IF(B12="","",($B$1&TEXT(IF(B12="","",COUNTA($B$5:B12)),"00"))) | C12: =IF(B12="",($B$1&TEXT(IF(B12="",COUNTA($B$5:B12),1),"00")),A12)&IF(B12<>"",TEXT(1,"00"),TEXT(IF(A12<>"",1,RIGHT(C11,2)+1),"00")) -> OTH20302 | D12: トークン有効期限が切れている（リソースサーバー）
A13: =IF(B13="","",($B$1&TEXT(IF(B13="","",COUNTA($B$5:B13)),"00"))) | C13: =IF(B13="",($B$1&TEXT(IF(B13="",COUNTA($B$5:B13),1),"00")),A13)&IF(B13<>"",TEXT(1,"00"),TEXT(IF(A13<>"",1,RIGHT(C12,2)+1),"00")) -> OTH20303 | D13: 認可サーバーを経由しない

Sheet 認可サーバーの設定について
B2: 認可サーバー
C4: Realm：spring-functionaltest
C5: user：demo/demo
C7: 項目名 | D7: 説明 | E7: 値
C8: SSO Session Idle | D8: セッションが期限切れになる前にアイドル状態であることが許される時間。 トークンとブラウザ・セッションは、セッションの有効期限が切れると無効になる。 | E8: 3m
C9: SSO Session Max | D9: セッションの有効期限が切れるまでの最大時間。 トークンとブラウザ・セッションは、セッションの有効期限が切れると無効になる。 | E9: 5h
C11: Client：ReadClient
C12: 項目名 | D12: 説明 | E12: 値
C13: Access Token Lifespan | D13: アクセストークンが失効するまでの最大時間。 新しいアクセストークンが発行されると、そのアクセストークンの有効期間は再設定される。 | E13: 60s
C14: Client Session Idle | D14: クライアント・セッションが期限切れになる前にアイドルであることを許される時間。 アクセストークンがリフレッシュされると、クライアントセッションのアイドル時間もリセットされる。 | E14: 3m （明示的に設定していないためSSOと同じ）
C15: Client Session Max | D15: クライアント・セッションの有効期限が切れるまでの最大時間。 クライアントセッションの最大時間はリフレッシュトークンの使用によってリセットされない。 | E15: 5h （明示的に設定していないためSSOと同じ）
C16: Client Scopes | D16: 許可されるスコープ | E16: READ
C18: Client：testClient
C19: 項目名 | D19: 説明 | E19: 値
C20: Access Token Lifespan | D20: アクセストークンが失効するまでの最大時間。 新しいアクセストークンが発行されると、そのアクセストークンの有効期間は再設定される。 | E20: 90s
C21: Client Session Idle | D21: クライアント・セッションが期限切れになる前にアイドルであることを許される時間。 アクセストークンがリフレッシュされると、クライアントセッションのアイドル時間もリセットされる。 | E21: 2m
C22: Client Session Max | D22: クライアント・セッションの有効期限が切れるまでの最大時間。 クライアントセッションの最大時間はリフレッシュトークンの使用によってリセットされない。 | E22: 3m
C23: Client Scopes | D23: 許可されるスコープ | E23: READ, CREATE, UPDATE, DELETE
B25: 基本的な値とその挙動について
C26: ■Access Token Lifespan < Client Session Idle < Client Session Max の場合
C28: リフレッシュされない期間
C29: 0s ～ (Access Token Lifespan - 60s)
C30: ※60sはSpringSecurityの仕様
C32: リフレッシュされる期間
C33: (Access Token Lifespan - 60s) ～ Client Session Idle
C34: ・Access Token Lifespan：更新される
C35: ・Client Session Idle：更新される
C36: ・Client Session Max：更新されない
C38: リフレッシュされない期間
C39: Client Session Idle ～
C40: ※アプリ側でエラーハンドリングを実施し、リフレッシュできるようにしているが、認可サーバー的にはエラーを返して終わり
... C53: ※アプリ側でエラーハンドリングを実施し、リフレッシュできるようにしているが、認可サーバー的にはエラーを返して終わり
B55: 認可の仕組み
C57: 簡単に記載すると、認可サーバーに登録されたClientが許可しているスコープ × クライアントアプリが設定したスコープで決定される。
C58: なお、認可サーバーで許可していないスコープをクライアントアプリ側が設定してきた場合は、認可サーバーからトークンが取得できずエラーとなる。
C60: 例えば
C61: ・testClient(READ, CREATE, UPDATE, DELETE)
C62: ・アプリ（READ, DELETE）
C63: の場合、許可されるスコープはREADとDELETEのみになる。
C65: ・readClient(READ)
...

Sheet OTH201
A1: 試験項目表 | C1: 件数 | D1: 機能ID/機能名 | E1: 大項目ID/大項目名 | F1: 作成者/作成日 | G1: 更新者/更新日 | H1: レビュー実施者/ レビュー日
A2: 大中項目へ | C2: =COUNTIFS($B$9:$B$65495,"<>",$J$9:$J$65495,"<>論理削除") -> 25 | D2: =大中項目!B1 -> OTH2 | E2: {=MID(CELL("filename", A1), FIND("]", CELL("filename", A1)) + 1, 255)} -> OTH201
D3: =大中項目!B2 -> OAuth2.0 | E3: =INDEX(大中項目!B:B, MATCH(E2, 大中項目!A:A, 0)) -> 認可コードグラント
A5: 特記事項
A6: [目的] 認可グラントによる挙動の確認を行う。 [補足] 本項における試験条件は以下とする。 ・認可コードグラント ・リソースサーバ～認可サーバ間のアクセストークンの連携方法・・・JWT
A8: 中項目ID | B8: Case ID | C8: 分類 | D8: 試験項目 | E8: 試験条件 | F8: 試験条件詳細【事前条件】 | G8: 試験条件詳細【実施条件】 | H8: 確認内容 | I8: 確認方法
A9: OTH20101 | B9: =IF(A9<>"",1,INDIRECT(ADDRESS(ROW(B9)-1,COLUMN(B9),4))+1) -> 1 | C9: 正常 | D9: ・認可コードグラント ・全スコープ × 全スコープ ・GET(intercepturl) | E9: ・認可コードグラントで認可処理を行う ・認可サーバーのClientは全スコープを許可する ・アプリ側で作成するClientは全スコープを対象とする ・リソースサーバー側でintercept-urlを使用した認可を実施 ・READスコープでリソースサーバーにアクセスする | F9: １．認可サーバーに全スコープ（READ/CREATE/UPDATE/DELETE）に対する権限を持つClientを作成済みであること ２．上記Clientを使用可能なユーザが認可サーバーに登録されていること | G9: １．TODO一覧取得処理を行う | H9: ・ログに全スコープを対象としていることが表示されること ・TODO一覧画面が表示できること。 | I9: Selenium:○
B10: =IF(A10<>"",1,INDIRECT(ADDRESS(ROW(B10)-1,COLUMN(B10),4))+1) -> 2 | C10: 正常 | D10: ・認可コードグラント ・全スコープ × 全スコープ ・POST(intercepturl) | E10: ・認可コードグラントで認可処理を行う ・認可サーバーのClientは全スコープを許可する ・アプリ側で作成するClientは全スコープを対象とする ・リソースサーバー側でintercept-urlを使用した認可を実施 ・CREATEスコープでリソースサーバーにアクセスする | F10: １．認可サーバーに全スコープ（READ/CREATE/UPDATE/DELETE）に対する権限を持つClientを作成済みであること ２．上記Clientを使用可能なユーザが認可サーバーに登録されていること ３．TODO一覧画面を表示済み | G10: １．TODO一覧画面からTODOタスクを作成する | H10: ・ログに全スコープを対象としていることが表示されること ・ログに作成成功が出力されていること ・作成したタスクがTODO一覧画面に表示されていること | I10: Selenium:○
B11: =IF(A11<>"",1,INDIRECT(ADDRESS(ROW(B11)-1,COLUMN(B11),4))+1) -> 3 | C11: 正常 | D11: ・認可コードグラント ・全スコープ × 全スコープ ・PUT(intercepturl) | E11: ・認可コードグラントで認可処理を行う ・認可サーバーのClientは全スコープを許可する ・アプリ側で作成するClientは全スコープを対象とする ・リソースサーバー側でintercept-urlを使用した認可を実施 ・UPDATEスコープでリソースサーバーにアクセスする | F11: １．認可サーバーに全スコープ（READ/CREATE/UPDATE/DELETE）に対する権限を持つClientを作成済みであること ２．上記Clientを使用可能なユーザが認可サーバーに登録されていること ３．TODOタスクを作成済み ４．TODO一覧画面を表示済み | G11: １．TODO一覧画面からTODOタスクを更新する | H11: ・ログに全スコープを対象としていることが表示されること ・ログに更新成功が出力されていること ・タスクのFinishボタンが削除されていること ※タスクに取り消し線が付くとともにボタンが消える | I11: Selenium:○
B12: =IF(A12<>"",1,INDIRECT(ADDRESS(ROW(B12)-1,COLUMN(B12),4))+1) -> 4 | C12: 正常 | D12: ・認可コードグラント ・全スコープ × 全スコープ ・DELETE(intercepturl) | E12: ・認可コードグラントで認可処理を行う ・認可サーバーのClientは全スコープを許可する ・アプリ側で作成するClientは全スコープを対象とする ・リソースサーバー側でintercept-urlを使用した認可を実施 ・DELETEスコープでリソースサーバーにアクセスする | F12: １．認可サーバーに全スコープ（READ/CREATE/UPDATE/DELETE）に対する権限を持つClientを作成済みであること ２．上記Clientを使用可能なユーザが認可サーバーに登録されていること ３．TODOタスクを作成済み ４．TODO一覧画面を表示済み | G12: １．TODO一覧画面からTODOタスクをs削除する | H12: ・ログに全スコープを対象としていることが表示されること ・ログに削除成功が出力されていること ・タスクがTODO一覧画面から消えていること | I12: Selenium:○
B13: =IF(A13<>"",1,INDIRECT(ADDRESS(ROW(B13)-1,COLUMN(B13),4))+1) -> 5 | C13: 正常 | D13: ・認可コードグラント ・全スコープ × 全スコープ ・GET(MethodAnnotation) | E13: ・認可コードグラントで認可処理を行う ・認可サーバーのClientは全スコープを許可する ・アプリ側で作成するClientは全スコープを対象とする ・リソースサーバー側でMethodAnnotationを使用した認可を実施 ・READスコープでリソースサーバーにアクセスする | F13: １．認可サーバーに全スコープ（READ/CREATE/UPDATE/DELETE）に対する権限を持つClientを作成済みであること ２．上記Clientを使用可能なユーザが認可サーバーに登録されていること | G13: １．TODO一覧取得処理を行う | H13: ・ログに全スコープを対象としていることが表示されること ・TODO一覧画面が表示できること。 | I13: Selenium:○
B14: =IF(A14<>"",1,INDIRECT(ADDRESS(ROW(B14)-1,COLUMN(B14),4))+1) -> 6 | C14: 正常 | D14: ・認可コードグラント ・全スコープ × 全スコープ ・POST(MethodAnnotation) | E14: ・認可コードグラントで認可処理を行う ・認可サーバーのClientは全スコープを許可する ・アプリ側で作成するClientは全スコープを対象とする ・リソースサーバー側でMethodAnnotationを使用した認可を実施 ・CREATEスコープでリソースサーバーにアクセスする | F14: １．認可サーバーに全スコープ（READ/CREATE/UPDATE/DELETE）に対する権限を持つClientを作成済みであること ２．上記Clientを使用可能なユーザが認可サーバーに登録されていること ３．TODO一覧画面を表示済み | G14: １．TODO一覧画面からTODOタスクを作成する | H14: ・ログに全スコープを対象としていることが表示されること ・ログに作成成功が出力されていること ・作成したタスクがTODO一覧画面に表示されていること | I14: Selenium:○
B15: =IF(A15<>"",1,INDIRECT(ADDRESS(ROW(B15)-1,COLUMN(B15),4))+1) -> 7 | C15: 正常 | D15: ・認可コードグラント ・全スコープ × 全スコープ ・PUT(MethodAnnotation) | E15: ・認可コードグラントで認可処理を行う ・認可サーバーのClientは全スコープを許可する ・アプリ側で作成するClientは全スコープを対象とする ・リソースサーバー側でMethodAnnotationを使用した認可を実施 ・UPDATEスコープでリソースサーバーにアクセスする | F15: １．認可サーバーに全スコープ（READ/CREATE/UPDATE/DELETE）に対する権限を持つClientを作成済みであること ２．上記Clientを使用可能なユーザが認可サーバーに登録されていること ３．TODOタスクを作成済み ４．TODO一覧画面を表示済み | G15: １．TODO一覧画面からTODOタスクを更新する | H15: ・ログに全スコープを対象としていることが表示されること ・ログに更新成功が出力されていること ・タスクのFinishボタンが削除されていること ※タスクに取り消し線が付くとともにボタンが消える | I15: Selenium:○
B16: =IF(A16<>"",1,INDIRECT(ADDRESS(ROW(B16)-1,COLUMN(B16),4))+1) -> 8 | C16: 正常 | D16: ・認可コードグラント ・全スコープ × 全スコープ ・DELETE(MethodAnnotation) | E16: ・認可コードグラントで認可処理を行う ・認可サーバーのClientは全スコープを許可する ・アプリ側で作成するClientは全スコープを対象とする ・リソースサーバー側でMethodAnnotationを使用した認可を実施 ・DELETEスコープでリソースサーバーにアクセスする | F16: １．認可サーバーに全スコープ（READ/CREATE/UPDATE/DELETE）に対する権限を持つClientを作成済みであること ２．上記Clientを使用可能なユーザが認可サーバーに登録されていること ３．TODOタスクを作成済み ４．TODO一覧画面を表示済み | G16: １．TODO一覧画面からTODOタスクをs削除する | H16: ・ログに全スコープを対象としていることが表示されること ・ログに削除成功が出力されていること ・タスクがTODO一覧画面から消えていること | I16: Selenium:○
A17: OTH20102 | B17: =IF(A17<>"",1,INDIRECT(ADDRESS(ROW(B17)-1,COLUMN(B17),4))+1) -> 1 | C17: 正常 | D17: ・認可コードグラント ・READスコープ × READスコープ ・GET(intercepturl) | E17: ・認可コードグラントで認可処理を行う ・認可サーバーのClientはREADスコープのみを許可する ・アプリ側で作成するClientは全スコープを対象とする ・リソースサーバー側でintercept-urlを使用した認可を実施 ・READスコープでリソースサーバーにアクセスする | F17: １．認可サーバーにREADスコープに対する権限を持つClientを作成済みであること ２．上記Clientを使用可能なユーザが認可サーバーに登録されていること | G17: １．TODO一覧取得処理を行う | H17: ・ログにREADスコープを対象としていることが表示されること ・TODO一覧画面が表示できること。 | I17: Selenium:○
B18: =IF(A18<>"",1,INDIRECT(ADDRESS(ROW(B18)-1,COLUMN(B18),4))+1) -> 2 | C18: 正常 | D18: ・認可コードグラント ・READスコープ × READスコープ ・POST(intercepturl) | E18: ・認可コードグラントで認可処理を行う ・認可サーバーのClientはREADスコープのみを許可する ・アプリ側で作成するClientはREADスコープを対象とする ・リソースサーバー側でintercept-urlを使用した認可を実施 ・CREATEスコープでリソースサーバーにアクセスする | F18: １．認可サーバーにREADスコープに対する権限を持つClientを作成済みであること ２．上記Clientを使用可能なユーザが認可サーバーに登録されていること ３．TODO一覧画面を表示済み | G18: １．TODO一覧画面からTODOタスクを作成する | H18: ・ログにREADスコープを対象としていることが表示されること ・403エラーが返却されること ・TODO一覧画面にタスクが作成されていないこと | I18: Selenium:○
B19: =IF(A19<>"",1,INDIRECT(ADDRESS(ROW(B19)-1,COLUMN(B19),4))+1) -> 3 | C19: 正常 | D19: ・認可コードグラント ・READスコープ × READスコープ ・PUT(intercepturl) | E19: ・認可コードグラントで認可処理を行う ・認可サーバーのClientはREADスコープのみを許可する ・アプリ側で作成するClientはREADスコープを対象とする ・リソースサーバー側でintercept-urlを使用した認可を実施 ・UPDATEスコープでリソースサーバーにアクセスする | F19: １．認可サーバーにREADスコープに対する権限を持つClientを作成済みであること ２．上記Clientを使用可能なユーザが認可サーバーに登録されていること ３．TODOタスクを作成済み ４．TODO一覧画面を表示済み | G19: １．TODO一覧画面からTODOタスクを更新する | H19: ・ログにREADスコープを対象としていることが表示されること ・403エラーが返却されること ・TODO一覧画面でタスクが更新されていないこと | I19: Selenium:○
B20: =IF(A20<>"",1,INDIRECT(ADDRESS(ROW(B20)-1,COLUMN(B20),4))+1) -> 4 | C20: 正常 | D20: ・認可コードグラント ・READスコープ × READスコープ ・DELETE(intercepturl) | E20: ・認可コードグラントで認可処理を行う ・認可サーバーのClientはREADスコープのみを許可する ・アプリ側で作成するClientはREADスコープを対象とする ・リソースサーバー側でintercept-urlを使用した認可を実施 ・DELETEスコープでリソースサーバーにアクセスする | F20: １．認可サーバーにREADスコープに対する権限を持つClientを作成済みであること ２．上記Clientを使用可能なユーザが認可サーバーに登録されていること ３．TODOタスクを作成済み ４．TODO一覧画面を表示済み | G20: １．TODO一覧画面からTODOタスクをs削除する | H20: ・ログにREADスコープを対象としていることが表示されること ・403エラーが返却されること ・TODO一覧画面でタスクが削除されていないこと | I20: Selenium:○
B21: =IF(A21<>"",1,INDIRECT(ADDRESS(ROW(B21)-1,COLUMN(B21),4))+1) -> 5 | C21: 正常 | D21: ・認可コードグラント ・READスコープ × READスコープ ・GET(MethodAnnotation) | E21: ・認可コードグラントで認可処理を行う ・認可サーバーのClientはREADスコープのみを許可する ・アプリ側で作成するClientはREADスコープを対象とする ・リソースサーバー側でMethodAnnotationを使用した認可を実施 ・READスコープでリソースサーバーにアクセスする | F21: １．認可サーバーにREADスコープに対する権限を持つClientを作成済みであること ２．上記Clientを使用可能なユーザが認可サーバーに登録されていること | G21: １．TODO一覧取得処理を行う | H21: ・ログにREADスコープを対象としていることが表示されること ・TODO一覧画面が表示できること。 | I21: Selenium:○
B22: =IF(A22<>"",1,INDIRECT(ADDRESS(ROW(B22)-1,COLUMN(B22),4))+1) -> 6 | C22: 正常 | D22: ・認可コードグラント ・READスコープ × READスコープ ・POST(MethodAnnotation) | E22: ・認可コードグラントで認可処理を行う ・認可サーバーのClientはREADスコープのみを許可する ・アプリ側で作成するClientはREADスコープを対象とする ・リソースサーバー側でMethodAnnotationを使用した認可を実施 ・CREATEスコープでリソースサーバーにアクセスする | F22: １．認可サーバーにREADスコープに対する権限を持つClientを作成済みであること ２．上記Clientを使用可能なユーザが認可サーバーに登録されていること ３．TODO一覧画面を表示済み | G22: １．TODO一覧画面からTODOタスクを作成する | H22: ・ログにREADスコープを対象としていることが表示されること ・403エラーが返却されること ・TODO一覧画面にタスクが作成されていないこと | I22: Selenium:○
B23: =IF(A23<>"",1,INDIRECT(ADDRESS(ROW(B23)-1,COLUMN(B23),4))+1) -> 7 | C23: 正常 | D23: ・認可コードグラント ・READスコープ × READスコープ ・PUT(MethodAnnotation) | E23: ・認可コードグラントで認可処理を行う ・認可サーバーのClientはREADスコープのみを許可する ・アプリ側で作成するClientはREADスコープを対象とする ・リソースサーバー側でMethodAnnotationを使用した認可を実施 ・UPDATEスコープでリソースサーバーにアクセスする | F23: １．認可サーバーにREADスコープに対する権限を持つClientを作成済みであること ２．上記Clientを使用可能なユーザが認可サーバーに登録されていること ３．TODOタスクを作成済み ４．TODO一覧画面を表示済み | G23: １．TODO一覧画面からTODOタスクを更新する | H23: ・ログにREADスコープを対象としていることが表示されること ・403エラーが返却されること ・TODO一覧画面でタスクが更新されていないこと | I23: Selenium:○
B24: =IF(A24<>"",1,INDIRECT(ADDRESS(ROW(B24)-1,COLUMN(B24),4))+1) -> 8 | C24: 正常 | D24: ・認可コードグラント ・READスコープ × READスコープ ・DELETE(MethodAnnotation) | E24: ・認可コードグラントで認可処理を行う ・認可サーバーのClientはREADスコープのみを許可する ・アプリ側で作成するClientはREADスコープを対象とする ・リソースサーバー側でMethodAnnotationを使用した認可を実施 ・DELETEスコープでリソースサーバーにアクセスする | F24: １．認可サーバーにREADスコープに対する権限を持つClientを作成済みであること ２．上記Clientを使用可能なユーザが認可サーバーに登録されていること ３．TODOタスクを作成済み ４．TODO一覧画面を表示済み | G24: １．TODO一覧画面からTODOタスクをs削除する | H24: ・ログにREADスコープを対象としていることが表示されること ・403エラーが返却されること ・TODO一覧画面でタスクが削除されていないこと | I24: Selenium:○
A25: OTH20103 | B25: =IF(A25<>"",1,INDIRECT(ADDRESS(ROW(B25)-1,COLUMN(B25),4))+1) -> 1 | C25: クライアントエラー | D25: ・認可コードグラント ・READスコープ × READ,UPDATEスコープ ・GET(intercepturl) | E25: ・認可コードグラントで認可処理を行う ・認可サーバーのClientはREADスコープのみを許可する ・アプリ側で作成するClientはREADスコープとUPDATEスコープを対象とする ・リソースサーバー側でintercept-urlを使用した認可を実施 ・READスコープでリソースサーバーにアクセスする | F25: １．認可サーバーにREADスコープに対する権限を持つClientを作成済みであること ２．上記Clientを使用可能なユーザが認可サーバーに登録されていること | G25: １．TODO一覧取得処理を行う | H25: ・Resource Not Found画面へ遷移すること ※手動確認 認可サーバーのログに以下が出力されること KC-SERVICES0093: Invalid parameter value for: scope | I25: Selenium:○
B26: =IF(A26<>"",1,INDIRECT(ADDRESS(ROW(B26)-1,COLUMN(B26),4))+1) -> 2 | C26: クライアントエラー | D26: ・認可コードグラント ・READスコープ × READ,UPDATEスコープ ・GET(MethodAnnotation) | E26: ・認可コードグラントで認可処理を行う ・認可サーバーのClientはREADスコープのみを許可する ・アプリ側で作成するClientはREADスコープとUPDATEスコープを対象とする ・リソースサーバー側でMethodAnnotationを使用した認可を実施 ・READスコープでリソースサーバーにアクセスする | F26: １．認可サーバーにREADスコープに対する権限を持つClientを作成済みであること ２．上記Clientを使用可能なユーザが認可サーバーに登録されていること | G26: １．TODO一覧取得処理を行う | H26: ・Resource Not Found画面へ遷移すること ※手動確認 認可サーバーのログに以下が出力されること KC-SERVICES0093: Invalid parameter value for: scope ※OTH20103001と同様の挙動の為、実施しない （リソースサーバーまで到達しないため） | I26: Selenium:○ | J26: 論理削除
A27: OTH20104 | B27: =IF(A27<>"",1,INDIRECT(ADDRESS(ROW(B27)-1,COLUMN(B27),4))+1) -> 1 | C27: 正常 | D27: ・認可コードグラント ・全スコープ × READ,DELETEスコープ ・GET(intercepturl) | E27: ・認可コードグラントで認可処理を行う ・認可サーバーのClientは全スコープを許可する ・アプリ側で作成するClientはREADスコープとDELETEスコープを対象とする ・リソースサーバー側でintercept-urlを使用した認可を実施 ・READスコープでリソースサーバーにアクセスする | F27: １．認可サーバーに全スコープ（READ/CREATE/UPDATE/DELETE）に対する権限を持つClientを作成済みであること ２．上記Clientを使用可能なユーザが認可サーバーに登録されていること | G27: １．TODO一覧取得処理を行う | H27: ・ログに全スコープを対象としていることが表示されること ・TODO一覧画面が表示できること。 | I27: Selenium:○
B28: =IF(A28<>"",1,INDIRECT(ADDRESS(ROW(B28)-1,COLUMN(B28),4))+1) -> 2 | C28: 正常 | D28: ・認可コードグラント ・全スコープ × READ,DELETEスコープ ・POST(intercepturl) | E28: ・認可コードグラントで認可処理を行う ・認可サーバーのClientは全スコープを許可する ・アプリ側で作成するClientはREADスコープとDELETEスコープを対象とする ・リソースサーバー側でintercept-urlを使用した認可を実施 ・CREATEスコープでリソースサーバーにアクセスする | F28: １．認可サーバーに全スコープ（READ/CREATE/UPDATE/DELETE）に対する権限を持つClientを作成済みであること ２．上記Clientを使用可能なユーザが認可サーバーに登録されていること ３．TODO一覧画面を表示済み | G28: １．TODO一覧画面からTODOタスクを作成する | H28: ・ログにREADスコープとDELETEスコープを対象としていることが表示されること ・403エラーが返却されること ・TODO一覧画面にタスクが作成されていないこと | I28: Selenium:○
B29: =IF(A29<>"",1,INDIRECT(ADDRESS(ROW(B29)-1,COLUMN(B29),4))+1) -> 3 | C29: 正常 | D29: ・認可コードグラント ・全スコープ × READ,DELETEスコープ ・PUT(intercepturl) | E29: ・認可コードグラントで認可処理を行う ・認可サーバーのClientは全スコープを許可する ・アプリ側で作成するClientはREADスコープとDELETEスコープを対象とする ・リソースサーバー側でintercept-urlを使用した認可を実施 ・UPDATEスコープでリソースサーバーにアクセスする | F29: １．認可サーバーに全スコープ（READ/CREATE/UPDATE/DELETE）に対する権限を持つClientを作成済みであること ２．上記Clientを使用可能なユーザが認可サーバーに登録されていること ３．TODOタスクを作成済み ４．TODO一覧画面を表示済み | G29: １．TODO一覧画面からTODOタスクを更新する | H29: ・ログにREADスコープとDELETEスコープを対象としていることが表示されること ・403エラーが返却されること ・TODO一覧画面でタスクが更新されていないこと | I29: Selenium:○
B30: =IF(A30<>"",1,INDIRECT(ADDRESS(ROW(B30)-1,COLUMN(B30),4))+1) -> 4 | C30: 正常 | D30: ・認可コードグラント ・全スコープ × READ,DELETEスコープ ・DELETE(intercepturl) | E30: ・認可コードグラントで認可処理を行う ・認可サーバーのClientは全スコープを許可する ・アプリ側で作成するClientはREADスコープとDELETEスコープを対象とする ・リソースサーバー側でintercept-urlを使用した認可を実施 ・DELETEスコープでリソースサーバーにアクセスする | F30: １．認可サーバーに全スコープ（READ/CREATE/UPDATE/DELETE）に対する権限を持つClientを作成済みであること ２．上記Clientを使用可能なユーザが認可サーバーに登録されていること ３．TODOタスクを作成済み ４．TODO一覧画面を表示済み | G30: １．TODO一覧画面からTODOタスクをs削除する | H30: ・ログに全スコープを対象としていることが表示されること ・ログに削除成功が出力されていること ・タスクがTODO一覧画面から消えていること | I30: Selenium:○
B31: =IF(A31<>"",1,INDIRECT(ADDRESS(ROW(B31)-1,COLUMN(B31),4))+1) -> 5 | C31: 正常 | D31: ・認可コードグラント ・全スコープ × READ,DELETEスコープ ・GET(MethodAnnotation) | E31: ・認可コードグラントで認可処理を行う ・認可サーバーのClientは全スコープを許可する ・アプリ側で作成するClientはREADスコープとDELETEスコープを対象とする ・リソースサーバー側でMethodAnnotationを使用した認可を実施 ・READスコープでリソースサーバーにアクセスする | F31: １．認可サーバーに全スコープ（READ/CREATE/UPDATE/DELETE）に対する権限を持つClientを作成済みであること ２．上記Clientを使用可能なユーザが認可サーバーに登録されていること | G31: １．TODO一覧取得処理を行う | H31: ・ログに全スコープを対象としていることが表示されること ・TODO一覧画面が表示できること。 | I31: Selenium:○
B32: =IF(A32<>"",1,INDIRECT(ADDRESS(ROW(B32)-1,COLUMN(B32),4))+1) -> 6 | C32: 正常 | D32: ・認可コードグラント ・全スコープ × READ,DELETEスコープ ・POST(MethodAnnotation) | E32: ・認可コードグラントで認可処理を行う ・認可サーバーのClientは全スコープを許可する ・アプリ側で作成するClientはREADスコープとDELETEスコープを対象とする ・リソースサーバー側でMethodAnnotationを使用した認可を実施 ・CREATEスコープでリソースサーバーにアクセスする | F32: １．認可サーバーに全スコープ（READ/CREATE/UPDATE/DELETE）に対する権限を持つClientを作成済みであること ２．上記Clientを使用可能なユーザが認可サーバーに登録されていること ３．TODO一覧画面を表示済み | G32: １．TODO一覧画面からTODOタスクを作成する | H32: ・ログにREADスコープとDELETEスコープを対象としていることが表示されること ・403エラーが返却されること ・TODO一覧画面にタスクが作成されていないこと | I32: Selenium:○
B33: =IF(A33<>"",1,INDIRECT(ADDRESS(ROW(B33)-1,COLUMN(B33),4))+1) -> 7 | C33: 正常 | D33: ・認可コードグラント ・全スコープ × READ,DELETEスコープ ・PUT(MethodAnnotation) | E33: ・認可コードグラントで認可処理を行う ・認可サーバーのClientは全スコープを許可する ・アプリ側で作成するClientはREADスコープとDELETEスコープを対象とする ・リソースサーバー側でMethodAnnotationを使用した認可を実施 ・UPDATEスコープでリソースサーバーにアクセスする | F33: １．認可サーバーに全スコープ（READ/CREATE/UPDATE/DELETE）に対する権限を持つClientを作成済みであること ２．上記Clientを使用可能なユーザが認可サーバーに登録されていること ３．TODOタスクを作成済み ４．TODO一覧画面を表示済み | G33: １．TODO一覧画面からTODOタスクを更新する | H33: ・ログにREADスコープとDELETEスコープを対象としていることが表示されること ・403エラーが返却されること ・TODO一覧画面でタスクが更新されていないこと | I33: Selenium:○
B34: =IF(A34<>"",1,INDIRECT(ADDRESS(ROW(B34)-1,COLUMN(B34),4))+1) -> 8 | C34: 正常 | D34: ・認可コードグラント ・全スコープ × READ,DELETEスコープ ・DELETE(MethodAnnotation) | E34: ・認可コードグラントで認可処理を行う ・認可サーバーのClientは全スコープを許可する ・アプリ側で作成するClientはREADスコープとDELETEスコープを対象とする ・リソースサーバー側でMethodAnnotationを使用した認可を実施 ・DELETEスコープでリソースサーバーにアクセスする | F34: １．認可サーバーに全スコープ（READ/CREATE/UPDATE/DELETE）に対する権限を持つClientを作成済みであること ２．上記Clientを使用可能なユーザが認可サーバーに登録されていること ３．TODOタスクを作成済み ４．TODO一覧画面を表示済み | G34: １．TODO一覧画面からTODOタスクをs削除する | H34: ・ログに全スコープを対象としていることが表示されること ・ログに削除成功が出力されていること ・タスクがTODO一覧画面から消えていること | I34: Selenium:○

Sheet OTH202
A1: 試験項目表 | C1: 件数 | D1: 機能ID/機能名 | E1: 大項目ID/大項目名 | F1: 作成者/作成日 | G1: 更新者/更新日 | H1: レビュー実施者/ レビュー日
A2: 大中項目へ | C2: =COUNTIFS($B$9:$B$65495,"<>",$J$9:$J$65495,"<>論理削除") -> 5 | D2: =大中項目!B1 -> OTH2 | E2: {=MID(CELL("filename", A1), FIND("]", CELL("filename", A1)) + 1, 255)} -> OTH202
D3: =大中項目!B2 -> OAuth2.0 | E3: =INDEX(大中項目!B:B, MATCH(E2, 大中項目!A:A, 0)) -> アクセストークン
A5: 特記事項
A6: [目的] アクセストークンに関する挙動の確認を行う。 [補足] 本項における試験条件は以下とする。 ・認可コードグラント ・リソースサーバ～認可サーバ間のアクセストークンの連携方法・・・JWT
A8: 中項目ID | B8: Case ID | C8: 分類 | D8: 試験項目 | E8: 試験条件 | F8: 試験条件詳細【事前条件】 | G8: 試験条件詳細【実施条件】 | H8: 確認内容 | I8: 確認方法
A9: OTH20201 | B9: =IF(A9<>"",1,INDIRECT(ADDRESS(ROW(B9)-1,COLUMN(B9),4))+1) -> 1 | C9: 正常 | D9: ・リフレッシュされない期間に再アクセス | E9: ・認可コードグラントで認可処理を行う ・リソースサーバーへアクセス後再アクセスする | F9: １．認可サーバーに全スコープ（READ/CREATE/UPDATE/DELETE）に対する権限を持つClientを作成済みであること ２．上記Clientを使用可能なユーザが認可サーバーに登録されていること | G9: １．TODO一覧取得処理を行う ２．アクセストークンの有効期限内（0秒 ～ アクセストークンの有効期限-60秒）に再アクセスする | H9: ・アクセストークンが更新されていないこと ・アクセストークンの有効期限が更新されていないこと | I9: Selenium:○
B10: =IF(A10<>"",1,INDIRECT(ADDRESS(ROW(B10)-1,COLUMN(B10),4))+1) -> 2 | C10: 正常 | D10: ・リフレッシュされる期間内に再アクセス | E10: ・認可コードグラントで認可処理を行う ・リソースサーバーへアクセス後再アクセスする | F10: １．認可サーバーに全スコープ（READ/CREATE/UPDATE/DELETE）に対する権限を持つClientを作成済みであること ２．上記Clientを使用可能なユーザが認可サーバーに登録されていること | G10: １．TODO一覧取得処理を行う ２．リフレッシュトークンが実行される期間内（アクセストークンの有効期限-60秒～リフレッシュトークン有効期限内）に再アクセスする | H10: ・アクセストークンが更新されていること ・アクセストークンの有効期限が最大有効期限未満の場合アクセストークンの有効期限が更新されていること ・アクセストークンの有効期限が最大有効期限と同じ場合アクセストークンの有効期限が更新されていないこと ※OTH20201001と一緒に実施 | I10: Selenium:○
B11: =IF(A11<>"",1,INDIRECT(ADDRESS(ROW(B11)-1,COLUMN(B11),4))+1) -> 3 | C11: 正常 | D11: ・Clientのアイドル期間外に再アクセス | E11: ・認可コードグラントで認可処理を行う ・リソースサーバーへアクセス後再アクセスする | F11: １．認可サーバーに全スコープ（READ/CREATE/UPDATE/DELETE）に対する権限を持つClientを作成済みであること ２．上記Clientを使用可能なユーザが認可サーバーに登録されていること | G11: １．TODO一覧取得処理を行う ２．Clientのアイドル期間外に再アクセスする | H11: ・アクセストークンが更新されていること ・アクセストークンの有効期限が更新されていること ※クライアントアプリで認可サーバーに対し再アクセスを実施している | I11: Selenium:○
B12: =IF(A12<>"",1,INDIRECT(ADDRESS(ROW(B12)-1,COLUMN(B12),4))+1) -> 4 | C12: 正常 | D12: ・Clientのセッション保持期間外に再アクセス | E12: ・認可コードグラントで認可処理を行う ・リソースサーバーへアクセス後再アクセスする | F12: １．認可サーバーに全スコープ（READ/CREATE/UPDATE/DELETE）に対する権限を持つClientを作成済みであること ２．上記Clientを使用可能なユーザが認可サーバーに登録されていること | G12: １．TODO一覧取得処理を行う ２．Clientのセッション保持期間外に再アクセスする | H12: ・アクセストークンが更新されていること ・アクセストークンの有効期限が更新されていること ※クライアントアプリで認可サーバーに対し再アクセスを実施している ※OTH20201001と一緒に実施 | I12: Selenium:○
A13: OTH20201 | B13: =IF(A13<>"",1,INDIRECT(ADDRESS(ROW(B13)-1,COLUMN(B13),4))+1) -> 1 | C13: サーバーエラー | D13: ・アクセストークンを加工して送信する | E13: ・認可コードグラントで認可処理を行う ・取得したトークンを加工してリソースサーバーへ送信する | F13: １．認可サーバーに全スコープ（READ/CREATE/UPDATE/DELETE）に対する権限を持つClientを作成済みであること ２．上記Clientを使用可能なユーザが認可サーバーに登録されていること | G13: １．TODO一覧取得処理を行う ２．リソースサーバー送信前にヘッダからトークンを取得し、余分な文字列を付与する | H13: ・リソースサーバーでJWT認可に失敗すること ・401エラーとなること | I13: Selenium:○

Sheet OTH203
A1: 試験項目表 | C1: 件数 | D1: 機能ID/機能名 | E1: 大項目ID/大項目名 | F1: 作成者/作成日 | G1: 更新者/更新日 | H1: レビュー実施者/ レビュー日
A2: 大中項目へ | C2: =COUNTIFS($B$9:$B$65495,"<>",$J$9:$J$65495,"<>論理削除") -> 5 | D2: =大中項目!B1 -> OTH2 | E2: {=MID(CELL("filename", A1), FIND("]", CELL("filename", A1)) + 1, 255)} -> OTH203
D3: =大中項目!B2 -> OAuth2.0 | E3: =INDEX(大中項目!B:B, MATCH(E2, 大中項目!A:A, 0)) -> その他異常系
A5: 特記事項
A6: [目的] 認可コードグラントの各種異常系について実施する。 [補足] 本項における試験条件は以下とする。 ・認可コードグラント ・リソースサーバ～認可サーバ間のアクセストークンの連携方法・・・JWT
A8: 中項目ID | B8: Case ID | C8: 分類 | D8: 試験項目 | E8: 試験条件 | F8: 試験条件詳細【事前条件】 | G8: 試験条件詳細【実施条件】 | H8: 確認内容 | I8: 確認方法
A9: OTH20301 | B9: =IF(A9<>"",1,INDIRECT(ADDRESS(ROW(B9)-1,COLUMN(B9),4))+1) -> 1 | C9: クライアントエラー | D9: ・トークンエンドポイントの誤り | E9: ・認可コードグラントで認可処理を行う ・誤ったトークンエンドポイントにアクセスする | F9: １．認可サーバーに全スコープ（READ/CREATE/UPDATE/DELETE）に対する権限を持つClientを作成済みであること ２．上記Clientを使用可能なユーザが認可サーバーに登録されていること | G9: １．TODO一覧取得処理を行う | H9: ・Resource Not Found画面へ遷移すること | I9: Selenium:○
B10: =IF(A10<>"",1,INDIRECT(ADDRESS(ROW(B10)-1,COLUMN(B10),4))+1) -> 2 | C10: サーバーエラー | D10: 認可エンドポイントの誤り | E10: ・認可コードグラントで認可処理を行う ・誤った認可エンドポイントにアクセスする | F10: １．認可サーバーに全スコープ（READ/CREATE/UPDATE/DELETE）に対する権限を持つClientを作成済みであること ２．上記Clientを使用可能なユーザが認可サーバーに登録されていること | G10: １．TODO一覧取得処理を行う | H10: ・認可サーバーで404となること | I10: Selenium:○
B11: =IF(A11<>"",1,INDIRECT(ADDRESS(ROW(B11)-1,COLUMN(B11),4))+1) -> 3 | C11: サーバーエラー | D11: JWTエンドポイントの誤り | E11: ・認可コードグラントで認可処理を行う ・誤ったJWTエンドポイントにアクセスする | F11: １．認可サーバーに全スコープ（READ/CREATE/UPDATE/DELETE）に対する権限を持つClientを作成済みであること ２．上記Clientを使用可能なユーザが認可サーバーに登録されていること | G11: １．TODO一覧取得処理を行う ２．リソースサーバー送信直前にClientセッションが切れるまで待機する | H11: ・認可サーバーで404となること | I11: Selenium:○
A12: OTH20302 | B12: =IF(A12<>"",1,INDIRECT(ADDRESS(ROW(B12)-1,COLUMN(B12),4))+1) -> 1 | C12: サーバーエラー | D12: トークンの有効期限切れ（リソースサーバー） | E12: ・認可コードグラントで認可処理を行う ・JWT認証実施時にトークンの有効期限切れ | F12: １．認可サーバーに全スコープ（READ/CREATE/UPDATE/DELETE）に対する権限を持つClientを作成済みであること ２．上記Clientを使用可能なユーザが認可サーバーに登録されていること | G12: ・クライアントサーバより以下のスコープを指定しリソースへアクセスすること ・スコープ：READ ・リソースオーナの認証、認可を行うこと | H12: ・認可サーバーで401となること | I12: Selenium:○
A13: OTH20303 | B13: =IF(A13<>"",1,INDIRECT(ADDRESS(ROW(B13)-1,COLUMN(B13),4))+1) -> 1 | C13: 正常 | D13: 認可サーバーを経由しない | E13: ・トークンを取得せずにリソースサーバーへアクセスする | F13: なし | G13: ・リソースサーバーへアクセスする | H13: ・リソースサーバからWWW-Authenticateヘッダが返却されること | I13: Selenium:○
